Workbook

Sheet Info
A1: FILE TÍNH TOÁN & KIỂM NGHIỆM THIẾT BỊ — HỆ TRUYỀN ĐỘNG XE CON CẦU TRỤC DẦM ĐÔI (x = 2)
A2: Mã hồ sơ: CDRL-02 — Gói SOW-3.1 / SOW-3.3 (Khối 3 — CDR-EVT)
A3: Phiên bản Excel: v1.3 — Ngày: 26/10/2026 — Người lập (Writer): AI; Người duyệt: Nhóm 8.5-EMG (v1.3 chưa qua Checker)
A4: Lịch sử: v1.3 (26/10/2026) nhóm C — bộ thông số mô phỏng: mô hình 2 khối lượng (khối O), giới hạn điện áp & giảm từ thông (khối P), biến tần trung bình & DC-link (khối Q), kịch bản rút gọn TS-01/TS-02 (khối R), giả định [C] GiaDinh_K3 hàng 43–58, KT-34..KT-41, SRS-D14..D15, sheet Mo_phong; không đổi số nào của v1.2. v1.2 (25/10/2026) nhập i_thực = 155.34 (SEW R87), M_a,max, xác minh BE1 7 N·m, R_h Danotherm CBH 360, ACS380 tr.12/24 đối chiếu ảnh trang; v1.0 (24/10/2026) bản đầu; v1.1 (24/10/2026) xử lý Checker K6-2 (λ quy về U_N = 400 V), K6-3 (quán tính khi phanh), K6-4 (sheet WCCA), K7-1 (thử mô-men giữ ⇒ M_B ≥ 1.2·M_hold, M_B = 7 N·m), K8-1, K8-3.
A5: Baseline: SSoT-8.5EMG-v1.2 (P-01..P-20), SRS Baseline A.1 (ký 24/10/2026; SRS-PERM-04: k_dt ≥ 1.20). Trạng thái: ĐÃ DUYỆT — Cổng G4 đóng 24/10/2026.
A6: Phạm vi (QĐ-07): chỉ xét điều kiện vận hành lý tưởng — không mất điện, không E-STOP/dừng khẩn, không xét sự cố thiết bị.
A8: QUY ƯỚC MÀU
A9: Chữ xanh dương = số nhập (hằng số gốc / giả định / catalogue). Chữ đen = công thức. Chữ xanh lá = công thức lấy từ sheet khác.
A10: Nền vàng = ô quyết định của Người dùng (chọn ứng viên động cơ, tỷ số truyền thực tế, R_h, M_B...). Ứng viên động cơ đã chốt sel = 1 (QĐ-04).
A11: Mọi ô ở 'Tính chọn', 'Kiểm tra', 'Dẫn xuất' là công thức; không gõ lại hằng số (WORKFLOW_RULES §6).
A13: CẤU TRÚC SHEET
A14: Params — 20 thông số gốc P-01..P-20 (sao chép đúng SSoT v1.2).
... A44: 8) ĐC định mức 400 V/50 Hz chạy trên lưới 380 V: nghịch lưu chỉ tạo được k_u·U_dc/√2 nên ở gần v_max phải giảm từ thông (khối P, SRS-D14..D15); KT-37/38 kiểm dòng vẫn trong giới hạn.

Sheet Params
A1: Mã P-xx | B1: Ký hiệu | C1: Giá trị | D1: Đơn vị | E1: Loại [A/B/C] | F1: ID yêu cầu | G1: Nguồn | H1: Tên thông số (tham khảo)
A2: P-01 | B2: Q | C2: 12222 | D2: kg | E2: [A] | F2: SRS-PERM-01 | G2: Đề bài x = 2 (SSoT v1.2) | H2: Tải trọng nâng định mức
A3: P-02 | B3: m_nh | C3: 222 | D3: kg | E3: [A] | F3: SRS-PERM-01 | G3: Đề bài x = 2 | H3: Khối lượng cơ cấu nâng hạ
A4: P-03 | B4: m_xc | C4: 1800 | D4: kg | E4: [C] | F4: SRS-PERM-01 | G4: Giả định ~15% Q; kiểm tra lại Khối 2 (chưa có catalogue) | H4: Khối lượng bản thân xe con
A5: P-04 | B5: M_Σ | C5: =$C$2+$C$3+$C$4 | D5: kg | E5: [B] | F5: SRS-PERM-01 | G5: P-01+P-02+P-03 | H5: Tổng khối lượng đầy tải
A6: P-05 | B6: m_tĩnh | C6: =$C$3+$C$4 | D6: kg | E6: [B] | F6: SRS-PERM-01 | G6: P-02+P-03 | H6: Tổng khối lượng không tải
A7: P-06 | B7: h | C7: 12 | D7: m | E7: [A] | F7: SRS-PERM-03 | G7: Đề bài x = 2 | H7: Chiều cao nâng (dài cáp)
A8: P-07 | B8: ω_p | C8: =SQRT($C$19/$C$7) | D8: rad/s | E8: [B] | F8: SRS-PERM-03 | G8: √(g/h) | H8: Tần số góc con lắc
A9: P-08 | B9: T_p | C9: =2*PI()/$C$8 | D9: s | E9: [B] | F9: SRS-PERM-03 | G9: 2π/ω_p | H9: Chu kỳ con lắc
A10: P-09 | B10: v_max | C10: 0.12 | D10: m/s | E10: [A] | F10: SRS-PERM-02 | G10: Đề bài x = 2 | H10: Vận tốc di chuyển lớn nhất
A11: P-10 | B11: a_max | C11: 0.5 | D11: m/s² | E11: [A] | F11: SRS-FUNC-03, SRS-PERM-03 | G11: Đề bài | H11: Gia tốc cực đại cho phép
A12: P-11 | B12: ρ_max | C12: 2 | D12: m/s³ | E12: [A] | F12: SRS-FUNC-03, SRS-PERM-03 | G12: Đề bài | H12: Độ giật cực đại cho phép
A13: P-12 | B13: D_bx | C13: 0.25 | D13: m | E13: [C] | F13: SRS-PERM-01, SRS-PERM-02 | G13: Giả định SSoT (nguồn DIN 536 chưa có trong kho) | H13: Đường kính bánh xe
A14: P-13 | B14: w_0 | C14: 0.015 | D14: - | E14: [C] | F14: SRS-PERM-01 | G14: Giả định SSoT; dải SOW 0.012-0.018 | H14: Suất cản lăn riêng
A15: P-14 | B15: φ | C15: 0.2 | D15: - | E15: [C] | F15: SRS-PERM-01 | G15: Giả định SSoT (Bài 4 slide 43: truyền lực ma sát) | H15: Hệ số bám bánh thép-ray
A16: P-15 | B16: η | C16: 0.9 | D16: - | E16: [C] | F16: SRS-PERM-01 | G16: Giả định SSoT (bảo thủ cho geared motor) | H16: Hiệu suất cơ khí
A17: P-16 | B17: i | C17: 150 | D17: - | E17: [C] | F17: SRS-PERM-01, SRS-PERM-02 | G17: Giả định SSoT; Khối 3 dùng i_thực (SRS-D03) | H17: Tỷ số truyền sơ bộ
A18: P-17 | B18: Chế độ | C18: S3 - 40% | D18: - | E18: [C] | F18: SRS-PERM-04 | G18: IEC 60034-1 ([R4] tr.23) | H18: Chế độ làm việc định mức
A19: P-18 | B19: g | C19: 9.81 | D19: m/s² | E19: [C] | F19: SRS-PERM-01, SRS-PERM-03 | G19: Hằng số | H19: Gia tốc trọng trường
A20: P-19 | B20: U_lưới | C20: 380 | D20: V (±10%, 50 Hz) | E20: [C] | F20: SRS-PERM-04 | G20: Lưới hạ thế VN | H20: Nguồn điện lưới
A21: P-20 | B21: F_c.đầy | C21: =$C$5*$C$19*$C$14 | D21: N | E21: [B] | F21: SRS-PERM-01 | G21: M_Σ·g·w_0 | H21: Lực cản tĩnh đầy tải

Sheet GiaDinh_K3
A1: Mã | B1: Đại lượng | C1: Ký hiệu | D1: Giá trị | E1: Đơn vị | F1: Công thức / Ghi chú | G1: Nguồn công thức
A2: Phân giải số của P-17 và P-19 (không phải số mới)
A3: CD | B3: Hệ số đóng điện tương đối của S3 | C3: CD | D3: 0.4 | E3: - | F3: Từ P-17 'S3 - 40%' | G3: P-17; IEC 60034-1 [R4] tr.23
A4: Tck | B4: Chu kỳ chuẩn S3 | C4: T_ck | D4: 600 | E4: s | F4: 10 phút (SRS-PERM-04) | G4: SRS-PERM-04
A5: dU | B5: Dung sai điện áp lưới | C5: ΔU | D5: 0.1 | E5: - | F5: ±10% (P-19) | G5: P-19
A6: f_grid | B6: Tần số lưới | C6: f | D6: 50 | E6: Hz | F6: P-19 | G6: P-19
A7: Giả định thiết kế [C] phát sinh ở Khối 3 (mỗi dòng: lý do + mốc kiểm tra)
A8: delta | B8: Hệ số kể đến quán tính chi tiết quay hộp số/khớp nối | C8: δ | D8: 1.15 | E8: - | F8: Giữa dải 1.1-1.2 (WORKFLOW §4.2-B4); kiểm tra lại khi có J hộp số SEW | G8: WORKFLOW_RULES §4.2-B4
A9: k_dan | B9: Tỷ lệ trọng lượng bám trên bánh dẫn | C9: k_dẫn | D9: 0.5 | E9: - | F9: 2/4 bánh dẫn (SAD TO-02 phương án A) | G9: WORKFLOW §4.2-B3; SAD §3.2
A10: n_trip | B10: Số hành trình trong một chu kỳ S3 | C10: n_ht | D10: 2 | E10: - | F10: 1 hành trình đầy tải (Tiến) + 1 hành trình không tải (Lùi); chiều dài hành trình suy ra để CD đúng 40% | G10: Giả định chu trình [C]
A11: a_set | B11: Gia tốc đặt S-curve | C11: a* | D11: 0.45 | E11: m/s² | F11: Dự trữ 10% dưới P-10; nằm trong dải QCD-Q03 [0.45; 0.50] | G11: SRS-FUNC-03; SOW QCD-Q03
A12: rho_set | B12: Độ giật đặt S-curve | C12: ρ* | D12: 1.8 | E12: m/s³ | F12: Dự trữ 10% dưới P-11; dải QCD-Q03 [1.80; 2.00] | G12: SRS-FUNC-03; SOW QCD-Q03
A13: eta_inv | B13: Hiệu suất biến tần | C13: η_inv | D13: 0.97 | E13: - | F13: Giá trị điển hình, chưa xác minh catalogue | G13: Giả định [C]
A14: U_chop | B14: Ngưỡng mở Chopper (thiết kế mô hình) | C14: U_chop | D14: 700 | E14: V | F14: Downstream #3: 700 ± 20 V; ngưỡng thật ACS380 chưa xác minh | G14: SRS Baseline A §4 #3
A15: U_dcmax | B15: Giới hạn điện áp DC-link | C15: U_dc,max | D15: 780 | E15: V | F15: Downstream #3 | G15: SRS Baseline A §4 #3
A16: U_trip | B16: Ngưỡng ngắt quá áp (mô hình) | C16: U_trip | D16: 800 | E16: V | F16: Downstream #3: 800 ± 10 V | G16: SRS Baseline A §4 #3
A17: kp_brake | B17: Hệ số an toàn phanh giữ | C17: k_p | D17: 1.25 | E17: - | F17: Cận trên dải 1.1-1.25 (TCVN 4244 §1.5.3.3 theo Baseline, chưa đối chiếu bản scan) | G17: [R1] qua WORKFLOW §4.2-C3
A18: k_hold | B18: Mô-men giữ thử trước khi nhả phanh (bội số M_N) | C18: M_hold/M_N | D18: 1 | E18: - | F18: Cận dưới dải [100%; 150%] (Downstream #5) | G18: SRS Baseline A §4 #5
A19: k_test | B19: Hệ số dự trữ phanh khi thử mô-men giữ | C19: k_thử | D19: 1.2 | E19: - | F19: Phanh phải giữ được M_hold khi thử (SDD §5) | G19: Giả định [C]
... A36: PM_min | B36: Độ dự trữ pha tối thiểu vòng tốc độ | C36: PM_min | D36: 30 | E36: ° | F36: Thông lệ thiết kế (gián tiếp cho M_p ≤ 10%) | G36: Giả định [C]
A37: Ô quyết định của Người dùng (cổng G4)
A38: sel | B38: Ứng viên chọn (1 = DRN80M4 + ACS380-03A3-4; 2 = DRN90S4 + ACS380-04A0-4) | C38: sel | D38: 1 | E38: - | F38: ĐÃ CHỐT = 1 (QĐ-04, 24/10/2026): DRN80M4 + ACS380-03A3-4; chấp nhận biên quá tải 1.03 ở WC-5 | G38: Người dùng — QĐ-04
A39: i_in | B39: Tỷ số truyền thực tế của hộp số SEW R87 | C39: i_thực | D39: 155.34 | E39: - | F39: R87, tỷ số tổng 155.34 — SEW Drive Selection (ứng dụng xe con, 25/10/2026) | G39: [W-06]
A40: Ma_max | B40: Mô-men ra cho phép lớn nhất của hộp số R87 | C40: M_a,max | D40: 1550 | E40: N·m | F40: SEW Drive Selection: R87, i = 155.34 | G40: [W-06]
A41: FRa | B41: Tải hướng kính cho phép trên trục ra (n = 1400) | C41: F_Ra | D41: 17100 | E41: N | F41: SEW Drive Selection: R87 | G41: [W-06]
A42: Rh_set | B42: Điện trở xả hãm chọn | C42: R_h | D42: 210 | E42: Ω | F42: Danotherm CBH 360 C T 406 210R: 210 Ω ±10%, 200 W (40 °C), công tắc nhiệt — điện trở mẫu ABB cho ACS380-01A8…05A6-4 | G42: [W-05] tr.24; [W-09]
A43: Giả định mô phỏng [C] — Khối 4, nhóm C (26/10/2026): mô hình 2 khối lượng, giới hạn điện áp, biến tần trung bình, kịch bản rút gọn
A44: k_u | B44: Hệ số dự trữ điện áp điều chế (để vòng dòng còn biên) | C44: k_u | D44: 0.95 | E44: - | F44: U_1 ≤ k_u·U_dc/√2 (SVPWM tuyến tính); 5% dành cho điều chỉnh dòng | G44: Giả định [C]
A45: zeta | B45: Hệ số tắt dần con lắc | C45: ζ | D45: 0 | E45: - | F45: Bảo thủ: không tắt dần (SDD §3.4) | G45: Giả định [C]
A46: C_dc | B46: Điện dung tụ DC-link (mô hình) | C46: C_dc | D46: 0.00022 | E46: F | F46: Chưa có trong catalogue ACS380-03A3-4 — chưa xác minh. C lớn hơn ⇒ chopper ít tác động hơn (xem KT-39) | G46: Giả định [C]
A47: dU_hys | B47: Độ trễ đóng/cắt chopper | C47: ΔU_hys | D47: 20 | E47: V | F47: Chopper ON tại U_chop, OFF tại U_chop − ΔU_hys | G47: Giả định [C]
A48: Ts_sim | B48: Bước giải cố định Simulink | C48: T_s | D48: 5e-05 | E48: s | F48: ≤ 1e-4 s; Ts_I = 250 µs và Ts_w = 1 ms là bội nguyên (KT-40) | G48: DVP v1.2 §3.4; ICD §4
A49: enc_mod | B49: Mô hình đo tốc độ trong mô phỏng | C49: enc_model | D49: 0 | E49: - | F49: 0 = tốc độ lý tưởng + lọc T_fω (mặc định); 1 = lượng tử 4·N_enc sườn / Ts_w (chỉ khảo sát nhiễu: Δω·K_p,ω ≈ 1.1 A dao động i_sq) | G49: Giả định [C]
A50: t_mag | B50: Thời gian từ hóa trước khi nhả phanh | C50: t_mag | D50: 0.5 | E50: s | F50: ≥ 3T_r | G50: SDD §5.1 [C]
A51: t_test | B51: Thời gian thử mô-men giữ (phanh còn kẹp) | C51: t_test | D51: 0.2 | E51: s | F51: Tăng dốc 0.05 s, giữ 0.1 s, giảm dốc 0.05 s | G51: SDD §5.1 [C]
A52: t_open | B52: Thời gian chờ nhả phanh | C52: t_open | D52: 0.1 | E52: s | F52: Chưa xác minh BE1 | G52: SDD §5.1 [C]
A53: t_hx | B53: Thời gian ĐC giữ ω* = 0 thêm sau khi phanh kẹp | C53: t_hx | D53: 0.05 | E53: s | F53: S6 kéo dài t_close + t_hx | G53: SDD §5.1 [C]
A54: t_cmd | B54: Thời điểm nhấn lệnh chạy (tính từ READY) | C54: t_cmd | D54: 0.5 | E54: s | F54: Kịch bản rút gọn TS-01/TS-02 | G54: Giả định [C]
A55: T_run | B55: Thời gian chạy đều mỗi hành trình (rút gọn) | C55: T_run | D55: 10 | E55: s | F55: ≥ T_p để thấy dao động lắc khi chạy đều; thay cho 119 s của chu trình nhiệt (khối F vẫn dùng cho k_dt) | G55: Giả định [C]
... A58: mech_mod | B58: Mô hình cơ khí trong mô phỏng | C58: mech_model | D58: 0 | E58: - | F58: 0 = 2 khối lượng (mặc định, DV-01..07); 1 = khối cứng như Excel (tải gắn cứng, bỏ F_lắc) — chạy thêm cho DV-04 vì với 2 khối năng lượng hãm mỗi lần dừng chỉ ≈ 0–28 J, tùy pha lắc | G58: Giả định [C]

Sheet Catalogue
A1: Mã | B1: Thông số | C1: Ký hiệu | D1: Ứng viên 1 | E1: Ứng viên 2 | F1: Đang chọn | G1: Đơn vị | H1: Nguồn (trang/bảng)
A2: Động cơ SEW DRN.. IE3, 400 V, 50 Hz, 4 cực, S1
A3: mot_name | B3: Mã động cơ | D3: DRN80M4 | E3: DRN90S4 | F3: =INDEX(D3:E3,1,GiaDinh_K3!$D$38) | G3: - | H3: [W-01] tr.866
A4: P_N | B4: Công suất định mức (S1) | C4: P_N | D4: 0.75 | E4: 1.1 | F4: =INDEX(D4:E4,1,GiaDinh_K3!$D$38) | G4: kW | H4: [W-01] tr.866
A5: M_N | B5: Mô-men định mức | C5: M_N | D5: 4.95 | E5: 7.2 | F5: =INDEX(D5:E5,1,GiaDinh_K3!$D$38) | G5: N·m | H5: [W-01] tr.866
A6: n_N | B6: Tốc độ định mức | C6: n_N | D6: 1440 | E6: 1455 | F6: =INDEX(D6:E6,1,GiaDinh_K3!$D$38) | G6: vg/ph | H6: [W-01] tr.866
A7: I_N | B7: Dòng định mức (400 V) | C7: I_N | D7: 1.75 | E7: 2.55 | F7: =INDEX(D7:E7,1,GiaDinh_K3!$D$38) | G7: A | H7: [W-01] tr.866
A8: cosN | B8: Hệ số công suất | C8: cosφ_N | D8: 0.74 | E8: 0.73 | F8: =INDEX(D8:E8,1,GiaDinh_K3!$D$38) | G8: - | H8: [W-01] tr.866
A9: effN | B9: Hiệu suất 100% tải | C9: η_đc | D9: 0.829 | E9: 0.845 | F9: =INDEX(D9:E9,1,GiaDinh_K3!$D$38) | G9: - | H9: [W-01] tr.866
A10: IA | B10: Bội số dòng khởi động | C10: I_A/I_N | D10: 6.7 | E10: 6.9 | F10: =INDEX(D10:E10,1,GiaDinh_K3!$D$38) | G10: - | H10: [W-01] tr.866
A11: MA | B11: Bội số mô-men khởi động | C11: M_A/M_N | D11: 3.1 | E11: 2.7 | F11: =INDEX(D11:E11,1,GiaDinh_K3!$D$38) | G11: - | H11: [W-01] tr.866
A12: lamK | B12: Bội số mô-men tới hạn | C12: λ_K = M_K/M_N | D12: 3.4 | E12: 3.3 | F12: =INDEX(D12:E12,1,GiaDinh_K3!$D$38) | G12: - | H12: [W-01] tr.866
A13: MH | B13: Bội số mô-men cực tiểu (saddle) | C13: M_H/M_N | D13: 2.7 | E13: 2.1 | F13: =INDEX(D13:E13,1,GiaDinh_K3!$D$38) | G13: - | H13: [W-01] tr.866
A14: J_mot | B14: Quán tính rotor | C14: J_Mot | D14: 0.00247 | E14: 0.0054 | F14: =INDEX(D14:E14,1,GiaDinh_K3!$D$38) | G14: kg·m² | H14: [W-02] tr.24 (24.7 / 54 ×10⁻⁴)
A15: J_B | B15: Quán tính rotor kèm phanh | C15: J_BMot | D15: 0.00262 | E15: 0.00587 | F15: =INDEX(D15:E15,1,GiaDinh_K3!$D$38) | G15: kg·m² | H15: [W-02] tr.24 (26.2 / 58.7 ×10⁻⁴)
A16: brake | B16: Loại phanh tiêu chuẩn | C16: BE.. | D16: BE1 | E16: BE2 | F16: =INDEX(D16:E16,1,GiaDinh_K3!$D$38) | G16: - | H16: [W-02] tr.24; cấp BE2 = 14/20 N·m [W-03] tr.24-25
A17: Biến tần ABB ACS380 (3 pha 400 V)
A18: inv_name | B18: Mã biến tần | D18: ACS380-04xS-03A3-4 | E18: ACS380-04xS-04A0-4 | F18: =INDEX(D18:E18,1,GiaDinh_K3!$D$38) | G18: - | H18: [W-05] tr.12
A19: Iinv_N | B19: Dòng định mức | C19: I_N,inv | D19: 3.3 | E19: 4 | F19: =INDEX(D19:E19,1,GiaDinh_K3!$D$38) | G19: A | H19: [W-05] tr.12 (đã đối chiếu ảnh trang gốc)
A20: Pinv_N | B20: Công suất danh định | C20: P_N,inv | D20: 1.1 | E20: 1.5 | F20: =INDEX(D20:E20,1,GiaDinh_K3!$D$38) | G20: kW | H20: [W-05] tr.12
A21: I_Hd | B21: Dòng heavy-duty (cho phép 150% I_Hd 1 phút/10 phút) | C21: I_Hd | D21: 2.6 | E21: 3.3 | F21: =INDEX(D21:E21,1,GiaDinh_K3!$D$38) | G21: A | H21: [W-05] tr.12
A22: P_Hd | B22: Công suất heavy-duty | C22: P_Hd | D22: 0.75 | E22: 1.1 | F22: =INDEX(D22:E22,1,GiaDinh_K3!$D$38) | G22: kW | H22: [W-05] tr.12
A23: I_max | B23: Dòng ra cực đại (2 s khi khởi động) | C23: I_max | D23: 4.7 | E23: 5.9 | F23: =INDEX(D23:E23,1,GiaDinh_K3!$D$38) | G23: A | H23: [W-05] tr.12
A24: R_min | B24: Điện trở hãm tối thiểu | C24: R_min | D24: 99 | E24: 99 | F24: =INDEX(D24:E24,1,GiaDinh_K3!$D$38) | G24: Ω | H24: [W-05] tr.24
A25: R_max | B25: Điện trở hãm tối đa cho P_BRcont | C25: R_max | D25: 428 | E25: 285 | F25: =INDEX(D25:E25,1,GiaDinh_K3!$D$38) | G25: Ω | H25: [W-05] tr.24
A26: PBRc | B26: Công suất hãm liên tục | C26: P_BRcont | D26: 0.75 | E26: 1.1 | F26: =INDEX(D26:E26,1,GiaDinh_K3!$D$38) | G26: kW | H26: [W-05] tr.24
A27: PBRm | B27: Công suất hãm cực đại (xung ≤ 1 phút/10 phút) | C27: P_BRmax | D27: 1.13 | E27: 1.65 | F27: =INDEX(D27:E27,1,GiaDinh_K3!$D$38) | G27: kW | H27: [W-05] tr.24
A28: trise | B28: Thời gian tăng mô-men (bước định mức) | C28: t_rise,cat | D28: 0.01 | E28: 0.01 | F28: =INDEX(D28:E28,1,GiaDinh_K3!$D$38) | G28: s | H28: [W-05] tr.10: '< 10 ms'

Sheet Tính chọn
A1: Mã | B1: Đại lượng | C1: Ký hiệu | D1: Giá trị | E1: Đơn vị | F1: Công thức / Ghi chú | G1: Nguồn công thức
A2: A. Động học & phụ tải tĩnh — [R1 §2.4.7.2.2 qua Baseline], Bài 3 (Tải của TĐĐ) slide 4
A3: w_bx | B3: Tốc độ góc trục bánh xe | C3: ω_bx | D3: =2*Params!$C$10/Params!$C$13 | E3: rad/s | F3: 2·v_max/D_bx | G3: WORKFLOW §4.2-A2
A4: n_bx | B4: Tốc độ quay bánh xe | C4: n_bx | D4: =$D$3*60/(2*PI()) | E4: vg/ph | F4: 60·ω_bx/2π | G4: WORKFLOW §4.2-A2
A5: Fc_chk | B5: Lực cản tĩnh đầy tải (tính lại) | C5: F_c.đầy | D5: =Params!$C$5*Params!$C$19*Params!$C$14 | E5: N | F5: M_Σ·g·w_0 (phải = P-20) | G5: WORKFLOW §4.2-A3
A6: Fc0 | B6: Lực cản tĩnh không tải | C6: F_c.không | D6: =Params!$C$6*Params!$C$19*Params!$C$14 | E6: N | F6: m_tĩnh·g·w_0 | G6: WORKFLOW §4.2-A3
A7: P_t | B7: Công suất cản tĩnh trên trục ĐC | C7: P_tĩnh | D7: =Params!$C$21*Params!$C$10/Params!$C$16 | E7: W | F7: F_c·v/η | G7: WORKFLOW §4.2-A4
A8: B. Động lực học, lực kéo cực đại & bám ray — Bài 4 slide 43; WORKFLOW §4.2-B
A9: Fqt | B9: Lực quán tính cực đại (a_max) | C9: F_qt | D9: =Params!$C$5*Params!$C$11 | E9: N | F9: M_Σ·a_max | G9: WORKFLOW §4.2-B1
A10: Fmax | B10: Lực kéo cực đại khi tăng tốc | C10: F_max | D10: =Params!$C$21+$D$9 | E10: N | F10: F_c + F_qt (Downstream #6) | G10: WORKFLOW §4.2-B1
A11: Pmax | B11: Công suất đỉnh | C11: P_max | D11: =$D$10*Params!$C$10/Params!$C$16 | E11: W | F11: F_max·v/η | G11: WORKFLOW §4.2-B2
A12: Fbam | B12: Lực bám bánh dẫn đầy tải | C12: F_bám | D12: =Params!$C$15*GiaDinh_K3!$D$9*Params!$C$5*Params!$C$19 | E12: N | F12: φ·k_dẫn·M_Σ·g | G12: WORKFLOW §4.2-B3
A13: kbam | B13: Hệ số an toàn bám đầy tải | C13: k_bám | D13: =$D$12/$D$10 | E13: - | F13: F_bám/F_max | G13: WORKFLOW §4.2-B3
A14: Fbam0 | B14: Lực bám bánh dẫn không tải | C14: F_bám,0 | D14: =Params!$C$15*GiaDinh_K3!$D$9*Params!$C$6*Params!$C$19 | E14: N | F14: φ·k_dẫn·m_tĩnh·g | G14: WORKFLOW §4.2-B3
A15: Fmax0 | B15: Lực kéo cực đại không tải | C15: F_max,0 | D15: =$D$6+Params!$C$6*Params!$C$11 | E15: N | F15: F_c,0 + m_tĩnh·a_max | G15: WORKFLOW §4.2-B3
A16: kbam0 | B16: Hệ số an toàn bám không tải | C16: k_bám,0 | D16: =$D$14/$D$15 | E16: - | G16: WORKFLOW §4.2-B3
A17: C. Quy đổi về trục động cơ — Bài 3 slide 4-5; WORKFLOW §4.2-B4
A18: wN | B18: Tốc độ góc định mức ĐC | C18: ω_N | D18: =Catalogue!$F$6*2*PI()/60 | E18: rad/s | F18: n_N·2π/60 | G18: [W-01]
A19: i_yc | B19: Tỷ số truyền yêu cầu | C19: i_yc | D19: =$D$18/$D$3 | E19: - | F19: ω_N/ω_bx (để v = v_max ở 50 Hz) | G19: Bài 3 slide 4
A20: i_tt | B20: Tỷ số truyền dùng tính toán | C20: i_thực | D20: =IF(ISBLANK(GiaDinh_K3!$D$39),$D$19,GiaDinh_K3!$D$39) | E20: - | F20: Bằng i_thực nhập; nếu trống dùng i_yc (TBD) | G20: SRS-D03
A21: dv_i | B21: Sai lệch v ở 50 Hz nếu dùng i_thực | C21: Δv/v | D21: =$D$19/$D$20-1 | E21: - | F21: Biến tần bù bằng tần số; ghi nhận | G21: SRS-PERM-02
A22: dv_150 | B22: Sai lệch v ở 50 Hz nếu dùng i = 150 (P-16) | C22: Δv/v (i=150) | D22: =$D$19/Params!$C$17-1 | E22: - | F22: So với SRS-PERM-02 ±5% (biến tần bù được) | G22: P-16
A23: k_qd | B23: Hệ số quy đổi tịnh tiến–quay | C23: k_qđ | D23: =Params!$C$13/(2*$D$20) | E23: m/rad | F23: D_bx/(2·i) | G23: WORKFLOW §4.2-B4
A24: eps_s | B24: Gia tốc góc ĐC ứng với a* | C24: ε* | D24: =GiaDinh_K3!$D$11/$D$23 | E24: rad/s² | F24: a*/k_qđ | G24: Bài 3
A25: Mc | B25: Mô-men cản kéo đầy tải | C25: M_c,kéo | D25: =Params!$C$21*$D$23/Params!$C$16 | E25: N·m | F25: F_c·D/(2iη) (góc I, III) | G25: WORKFLOW §4.2-B4
A26: Mc0 | B26: Mô-men cản kéo không tải | C26: M_c,kéo,0 | D26: =$D$6*$D$23/Params!$C$16 | E26: N·m | G26: WORKFLOW §4.2-B4
A27: Mch | B27: Mô-men cản khi hãm đầy tải | C27: M_c,hãm | D27: =Params!$C$21*$D$23*Params!$C$16 | E27: N·m | F27: F_c·D·η/(2i) (góc II, IV) | G27: WORKFLOW §4.2-B4
A28: Jl | B28: Quán tính tải quy đổi đầy tải | C28: J_tải | D28: =GiaDinh_K3!$D$8*Params!$C$5*$D$23^2 | E28: kg·m² | F28: δ·M_Σ·k_qđ² | G28: WORKFLOW §4.2-B4
A29: Jl0 | B29: Quán tính tải quy đổi không tải | C29: J_tải,0 | D29: =GiaDinh_K3!$D$8*Params!$C$6*$D$23^2 | E29: kg·m² | F29: δ·m_tĩnh·k_qđ² | G29: WORKFLOW §4.2-B4
A30: JS | B30: Quán tính tổng đầy tải | C30: J_Σ | D30: =Catalogue!$F$15+$D$28 | E30: kg·m² | F30: J_BMot + J_tải | G30: WORKFLOW §4.2-B4
A31: JS0 | B31: Quán tính tổng không tải | C31: J_Σ,0 | D31: =Catalogue!$F$15+$D$29 | E31: kg·m² | G31: WORKFLOW §4.2-B4
A32: D. Mô-men cực đại & kiểm tra quá tải (λ) — WORKFLOW §4.2-C2; Bài 4 slide 12
A33: Mpk | B33: Mô-men ĐC cực đại khi tăng tốc đầy tải với a_max | C33: M_max | D33: =(Params!$C$21+GiaDinh_K3!$D$8*Params!$C$5*Params!$C$11)*$D$23/Params!$C$16+Catalogue!$F$15*Params!$C$11/$D$23 | E33: N·m | F33: (F_c+δM_Σa_max)k/η + J_B·a_max/k | G33: WORKFLOW §4.2-B4, C2
A34: Mpk0 | B34: Mô-men ĐC cực đại không tải với a_max | C34: M_max,0 | D34: =($D$6+GiaDinh_K3!$D$8*Params!$C$6*Params!$C$11)*$D$23/Params!$C$16+Catalogue!$F$15*Params!$C$11/$D$23 | E34: N·m | G34: WORKFLOW §4.2-B4
A35: lam_req | B35: Bội số mô-men yêu cầu | C35: M_max/M_N | D35: =$D$33/Catalogue!$F$5 | E35: - | G35: WORKFLOW §4.2-C2
A36: lam_avl | B36: Bội số khả dụng khi sụt áp -10% (quy về U_N động cơ) | C36: λ_K·(U_min/U_N)² | D36: =Catalogue!$F$12*(Params!$C$20*(1-GiaDinh_K3!$D$5)/GiaDinh_K3!$D$29)^2 | E36: - | F36: M_K ∝ U²; U_min = 342 V so với U_N = 400 V (Checker K6-2) | G36: WORKFLOW §4.2-C2
A37: Fk_cap | B37: Lực kéo tối đa ĐC tạo được ở -10% áp (trừ quán tính rotor ở a_max) | C37: F_k,max | D37: =($D$36*Catalogue!$F$5-Catalogue!$F$15*Params!$C$11/$D$23)*Params!$C$16/$D$23 | E37: N | F37: Dùng để kiểm Downstream #6 | G37: Tự dẫn
A38: E. Quỹ đạo S-curve 7 đoạn — [R9-11] Tho et al. 2020; WORKFLOW §4.2-D1
A39: Tj | B39: Thời gian tăng/giảm độ giật | C39: T_j | D39: =GiaDinh_K3!$D$11/GiaDinh_K3!$D$12 | E39: s | F39: a*/ρ* | G39: WORKFLOW §4.2-D1
A40: Ta | B40: Thời gian gia tốc không đổi | C40: T_a | D40: =Params!$C$10/GiaDinh_K3!$D$11-$D$39 | E40: s | F40: v_max/a* − T_j (>0 ⇒ đủ 3 đoạn) | G40: WORKFLOW §4.2-D1
...

Sheet Kiểm tra
A1: Mã KT | B1: Nội dung kiểm tra | C1: Giá trị tính | D1: Ngưỡng | E1: Kết quả | F1: Yêu cầu nguồn | G1: Ghi chú
A2: KT-01 | B2: Lực cản tĩnh tính lại khớp P-20 (sai lệch < 1 N) | C2: ='Tính chọn'!$D$5 | D2: =Params!$C$21 | E2: =IF(ABS(C2-D2)<1,"Đạt","Không đạt") | F2: P-20, K6
A3: KT-02 | B3: Hệ số bám đầy tải k_bám ≥ 1.20 | C3: ='Tính chọn'!$D$13 | D3: 1.2 | E3: =IF(C3>=D3,"Đạt","Không đạt") | F3: SRS-PERM-01
A4: KT-03 | B4: Hệ số bám không tải k_bám,0 ≥ 1.20 | C4: ='Tính chọn'!$D$16 | D4: 1.2 | E4: =IF(C4>=D4,"Đạt","Không đạt") | F4: SRS-PERM-01
A5: KT-04 | B5: Bội số mô-men catalogue λ_K ≥ 2.0 | C5: =Catalogue!$F$12 | D5: 2 | E5: =IF(C5>=D5,"Đạt","Không đạt") | F5: Downstream #7 | G5: [W-01]
A6: KT-05 | B6: Quá tải ở sụt áp -10%: λ_K·(342/400)² ≥ M_max/M_N | C6: ='Tính chọn'!$D$36 | D6: ='Tính chọn'!$D$35 | E6: =IF(C6>=D6,"Đạt","Không đạt") | F6: Downstream #7, SRS-PERM-01
A7: KT-06 | B7: Lực kéo ĐC tạo được ≥ F_max = 9,218 N (dải 9.25 ± 0.45 kN) | C7: ='Tính chọn'!$D$37 | D7: ='Tính chọn'!$D$10 | E7: =IF(C7>=D7,"Đạt","Không đạt") | F7: Downstream #6
A8: KT-07 | B8: k_dt ≥ 1.20 (SRS Baseline A.1 — có hiệu lực 24/10/2026) | C8: ='Tính chọn'!$D$60 | D8: 1.2 | E8: =IF(C8>=D8,"Đạt","Không đạt") | F8: SRS-PERM-04 (A.1)
A9: KT-08 | B9: k_dt ≤ 1.50 (cận trên SRS v1.2 — đã bỏ trong SRS Baseline A.1, ký 24/10/2026) | C9: ='Tính chọn'!$D$60 | D9: 1.5 | E9: ="Không áp dụng (SRS A.1 có hiệu lực, CR-01)" | F9: SRS-PERM-04 (v1.2 → A.1) | G9: Giữ để truy vết xung đột QĐ-02
A10: KT-09 | B10: P_đm ≤ min(2.2 kW; 1.5·P_max) — QCD-C01, cách hiểu QĐ-08 (so với P_max) | C10: =Catalogue!$F$4 | D10: =MIN(2.2,1.5*'Tính chọn'!$D$11/1000) | E10: =IF(C10<=D10,"Đạt","Không đạt") | F10: SOW QCD-C01 (QĐ-08) | G10: Trần = MIN(2.2; 1.5·P_max/1000)
A11: KT-10 | B11: Biến tần: I_Hd ≥ I_N động cơ | C11: =Catalogue!$F$21 | D11: =Catalogue!$F$7 | E11: =IF(C11>=D11,"Đạt","Không đạt") | F11: SRS-PERM-04
A12: KT-11 | B12: Biến tần: 1.5·I_Hd ≥ I_đỉnh tăng tốc | C12: ='Tính chọn'!$D$72 | D12: ='Tính chọn'!$D$71 | E12: =IF(C12>=D12,"Đạt","Không đạt") | F12: SRS-PERM-01
A13: KT-12 | B13: Biến tần: I_max ≥ I_đỉnh | C13: =Catalogue!$F$23 | D13: ='Tính chọn'!$D$71 | E13: =IF(C13>=D13,"Đạt","Không đạt") | F13: SRS-PERM-01
A14: KT-13 | B14: R_h ≥ R_min chopper | C14: =GiaDinh_K3!$D$42 | D14: ='Tính chọn'!$D$78 | E14: =IF(C14>=D14,"Đạt","Không đạt") | F14: SRS-FUNC-04
A15: KT-14 | B15: R_h ≤ min(U_chop²/P_hãm; R_max) | C15: =GiaDinh_K3!$D$42 | D15: ='Tính chọn'!$D$77 | E15: =IF(C15<=D15,"Đạt","Không đạt") | F15: SRS-FUNC-04, Downstream #3
A16: KT-15 | B16: P_BRmax biến tần ≥ P_hãm đỉnh | C16: =Catalogue!$F$27 | D16: ='Tính chọn'!$D$75/1000 | E16: =IF(C16>=D16,"Đạt","Không đạt") | F16: SRS-FUNC-04 | G16: đơn vị kW
A17: KT-16 | B17: U_dc không tải (lưới +10%) < ngưỡng chopper dưới (U_chop − 20 V) | C17: ='Tính chọn'!$D$84 | D17: =GiaDinh_K3!$D$14-20 | E17: =IF(C17<D17,"Đạt","Không đạt") | F17: Downstream #3 | G17: Chopper không băm khi đứng yên
A18: KT-17 | B18: Ngưỡng chopper < U_dc,max < ngưỡng trip | C18: =GiaDinh_K3!$D$15 | D18: =GiaDinh_K3!$D$16 | E18: =IF(AND(GiaDinh_K3!$D$14<C18,C18<D18),"Đạt","Không đạt") | F18: Downstream #3 | G18: Kiểm chứng U_dc(t) ở DV-04 (S)
A19: KT-18 | B19: S-curve: a* ≤ a_max | C19: =GiaDinh_K3!$D$11 | D19: =Params!$C$11 | E19: =IF(C19<=D19,"Đạt","Không đạt") | F19: SRS-FUNC-03
A20: KT-19 | B20: S-curve: ρ* ≤ ρ_max | C20: =GiaDinh_K3!$D$12 | D20: =Params!$C$12 | E20: =IF(C20<=D20,"Đạt","Không đạt") | F20: SRS-FUNC-03
A21: KT-20 | B21: S-curve đủ 3 đoạn: a*²/ρ* < v_max | C21: ='Tính chọn'!$D$43 | D21: =Params!$C$10 | E21: =IF(C21<D21,"Đạt","Không đạt") | F21: SRS-FUNC-03
A22: KT-21 | B22: Góc lắc dư ≤ θ_0 = 2.92° | C22: ='Tính chọn'!$D$46 | D22: ='Tính chọn'!$D$47 | E22: =IF(C22<=D22,"Đạt","Không đạt") | F22: SRS-PERM-03 (tham khảo) | G22: Ước lượng; kiểm chứng S ở DV-07
A23: KT-22 | B23: Δt_torque (MO) ≤ 10 ms | C23: ='Tính chọn'!$D$131 | D23: 0.01 | E23: =IF(C23<=D23,"Đạt","Không đạt") | F23: Downstream #4 | G23: Catalogue ACS380 < 10 ms [W-05]
A24: KT-23 | B24: PM vòng tốc độ đầy tải ≥ PM_min | C24: ='Tính chọn'!$D$152 | D24: =GiaDinh_K3!$D$36 | E24: =IF(C24>=D24,"Đạt","Không đạt") | F24: Downstream #1 (gián tiếp) | G24: M_p kiểm chứng S ở DV-06
A25: KT-24 | B25: PM vòng tốc độ không tải ≥ PM_min | C25: ='Tính chọn'!$D$166 | D25: =GiaDinh_K3!$D$36 | E25: =IF(C25>=D25,"Đạt","Không đạt") | F25: Downstream #1 (gián tiếp)
A26: KT-25 | B26: Phân giải encoder Δv ≤ ngưỡng cấm đảo chiều 0.002 m/s | C26: ='Tính chọn'!$D$170 | D26: =GiaDinh_K3!$D$32 | E26: =IF(C26<=D26,"Đạt","Không đạt") | F26: Downstream #5
A27: KT-26 | B27: Tốc độ bò trong [0.030; 0.036] m/s | C27: ='Tính chọn'!$D$172 | D27: =0.3*Params!$C$10 | E27: =IF(AND(C27>=0.25*Params!$C$10-0.000000001,C27<=0.3*Params!$C$10+0.000000001),"Đạt","Không đạt") | F27: Downstream #8
A28: KT-27 | B28: M_B ≥ max(k_p·M_c; 1.2·M_hold) (giữ xe & chịu mô-men thử) | C28: =GiaDinh_K3!$D$20 | D28: ='Tính chọn'!$D$88 | E28: =IF(C28>=D28,"Đạt","Không đạt") | F28: SRS-FUNC-02 | G28: [R1] qua Baseline
A29: KT-28 | B29: M_B ≤ giới hạn không trượt đầy tải | C29: =GiaDinh_K3!$D$20 | D29: ='Tính chọn'!$D$89 | E29: =IF(C29<=D29,"Đạt","Không đạt") | F29: SRS-PERM-01
A30: KT-29 | B30: M_B ≤ giới hạn không trượt không tải (chỉ khi phanh khẩn lúc đang chạy) | C30: =GiaDinh_K3!$D$20 | D30: ='Tính chọn'!$D$90 | E30: ="Không áp dụng (QĐ-07: vận hành lý tưởng, không dừng khẩn/mất điện)" | F30: SRS-FUNC-02 | G30: DFMEA FM-07 — Không áp dụng
A31: KT-30 | B31: Độ trôi danh nghĩa Δs ≤ 10 mm | C31: ='Tính chọn'!$D$94 | D31: 10 | E31: =IF(C31<=D31,"Đạt","Không đạt") | F31: SRS-FUNC-02 | G31: Kiểm chứng S ở DV-02
A32: KT-31 | B32: Vận tốc định mức: |Δv/v| khi dùng i_thực ≤ 5% (hoặc biến tần bù tần số) | C32: ='Tính chọn'!$D$21 | D32: 0.05 | E32: =IF(ISBLANK(GiaDinh_K3!$D$39),"TBD (chưa có i_thực)",IF(ABS(C32)<=D32,"Đạt","Không đạt — bù bằng tần số")) | F32: SRS-PERM-02
A33: KT-33 | B33: Hộp số R87: mô-men ra đỉnh (F_c + δ·M_Σ·a_max)·D/2 ≤ M_a,max | C33: =(Params!$C$21+GiaDinh_K3!$D$8*Params!$C$5*Params!$C$11)*Params!$C$13/2 | D33: =GiaDinh_K3!$D$40 | E33: =IF(C33<=D33,"Đạt","Không đạt") | F33: SRS-PERM-01 | G33: [W-06]
A34: KT-32 | B34: Kết quả mô phỏng DV-01..07 | E34: ="TBD — Report: chưa chạy" | F34: DVP v1.2 | G34: WORKFLOW §7.5
A35: KT-34 | B35: Mô hình 2 khối: (m_xc + m_pend)·g·w0 khớp P-20 (sai lệch < 1 N) | C35: ='Tính chọn'!$D$180 | D35: =Params!$C$21 | E35: =IF(ABS(C35-D35)<1,"Đạt","Không đạt") | F35: P-20, K6 | G35: Trọng lượng tải vẫn đè lên bánh
A36: KT-35 | B36: Cộng hưởng xe–tải ω_r ≪ tần số cắt vòng tốc độ (ω_c/ω_r ≥ 10) | C36: ='Tính chọn'!$D$153/'Tính chọn'!$D$183 | D36: 10 | E36: =IF(C36>=D36,"Đạt","Không đạt") | F36: SRS-PERM-02 | G36: Vòng tốc độ chỉ thấy J_rig
A37: KT-36 | B37: κ_2m nằm trong [κ_đầy; κ_không] đã kiểm ở KT-23/24 ⇒ PM ≥ 34.6° | C37: ='Tính chọn'!$D$189 | D37: ='Tính chọn'!$D$139 | E37: =IF(AND(C37>='Tính chọn'!$D$138,C37<=D37),"Đạt","Không đạt") | F37: Downstream #1 (gián tiếp) | G37: PM của SO nhỏ nhất ở hai biên κ
A38: KT-37 | B38: Giảm từ thông (lưới −10%): i_sq cần ≤ i_sq,lim | C38: ='Tính chọn'!$D$206 | D38: ='Tính chọn'!$D$125 | E38: =IF(C38<=D38,"Đạt","Không đạt") | F38: SRS-PERM-01, IF-04 | G38: Bảo thủ (khối cứng)
A39: KT-38 | B39: Giảm từ thông (lưới −10%): dòng stator hiệu dụng ≤ 1.5·I_Hd | C39: ='Tính chọn'!$D$208 | D39: ='Tính chọn'!$D$72 | E39: =IF(C39<=D39,"Đạt","Không đạt") | F39: SRS-PERM-04 | G39: [W-05] tr.12
A40: KT-39 | B40: DC-link: với mô hình khối cứng (mech_model = 1), chopper tác động khi dừng đầy tải (E_Rh > E_C) ⇒ DV-04 quan sát được | C40: ='Tính chọn'!$D$82 | D40: ='Tính chọn'!$D$213 | E40: =IF(C40>D40,"Đạt","Không đạt") | F40: SRS-FUNC-04 | G40: Phụ thuộc C_dc [C] chưa xác minh; mô hình 2 khối cho E ≈ 0–28 J nên có thể không đóng chopper
...

Sheet Dẫn xuất
A1: Mã SRS-Dxx | B1: Ràng buộc thiết kế dẫn xuất | C1: Giá trị | D1: Đơn vị | E1: Yêu cầu cha | F1: Bước tính sinh ra (sheet/khối) | G1: Phương pháp KC | H1: DV
A2: SRS-D01 | B2: Lực kéo cực đại khi tăng tốc đầy tải; giới hạn i_sq chống trượt | C2: ='Tính chọn'!$D$10 | D2: N | E2: SRS-PERM-01 | F2: Tính chọn B, J (isqmax) | G2: A | H2: DV-05
A3: SRS-D02 | B3: Bội số mô-men yêu cầu M_max/M_N (≤ λ_K·(342/400)²) | C3: ='Tính chọn'!$D$35 | D3: - | E3: SRS-PERM-01, SRS-PERM-04 | F3: Tính chọn D | G3: A / I | H3: DV-08
A4: SRS-D03 | B4: Tỷ số truyền dùng cho quy đổi (i_thực; TBD → i_yc) | C4: ='Tính chọn'!$D$20 | D4: - | E4: SRS-PERM-02 | F4: Tính chọn C | G4: I | H4: DV-06
A5: SRS-D04a | B5: Công suất định mức động cơ chọn | C5: =Catalogue!$F$4 | D5: kW | E5: SRS-PERM-04 | F5: Catalogue + Tính chọn F | G5: A / I | H5: DV-08
A6: SRS-D04b | B6: Dòng heavy-duty biến tần chọn | C6: =Catalogue!$F$21 | D6: A | E6: SRS-PERM-04 | F6: Catalogue + Tính chọn G | G6: I | H6: DV-08
A7: SRS-D05a | B7: Điện trở xả hãm R_h | C7: =GiaDinh_K3!$D$42 | D7: Ω | E7: SRS-FUNC-04 | F7: Tính chọn H | G7: A / S | H7: DV-04
A8: SRS-D05b | B8: Công suất hãm đỉnh cần hấp thụ | C8: ='Tính chọn'!$D$75 | D8: W | E8: SRS-FUNC-04 | F8: Tính chọn H | G8: A / S | H8: DV-04
A9: SRS-D05c | B9: Ngưỡng mở chopper (mô hình) | C9: =GiaDinh_K3!$D$14 | D9: V | E9: SRS-FUNC-04 | F9: Downstream #3 | G9: S | H9: DV-04
A10: SRS-D06a | B10: Gia tốc đặt S-curve a* | C10: =GiaDinh_K3!$D$11 | D10: m/s² | E10: SRS-FUNC-03, SRS-PERM-03 | F10: Tính chọn E | G10: A / S | H10: DV-03, DV-07
A11: SRS-D06b | B11: Độ giật đặt S-curve ρ* | C11: =GiaDinh_K3!$D$12 | D11: m/s³ | E11: SRS-FUNC-03, SRS-PERM-03 | F11: Tính chọn E | G11: A / S | H11: DV-03, DV-07
A12: SRS-D07a | B12: Hệ số K_p,ω PI tốc độ (SO tại J_tune) | C12: ='Tính chọn'!$D$135 | D12: A·s/rad | E12: SRS-PERM-02 (Downstream #1) | F12: Tính chọn L | G12: S | H12: DV-06
A13: SRS-D07b | B13: Hằng số T_i,ω PI tốc độ | C13: ='Tính chọn'!$D$136 | D13: s | E13: SRS-PERM-02 (Downstream #1) | F13: Tính chọn L | G13: S | H13: DV-06
A14: SRS-D08 | B14: Sai lệch xác lập e_xl (khâu I ⇒ 0) — ngưỡng | C14: =GiaDinh_K3!$D$35 | D14: - | E14: SRS-PERM-02 (Downstream #2) | F14: SDD §4 | G14: S | H14: DV-06
A15: SRS-D09a | B15: Hệ số K_p,I PI dòng (MO) | C15: ='Tính chọn'!$D$128 | D15: V/A | E15: SRS-FUNC-01 (Downstream #4) | F15: Tính chọn K | G15: S | H15: DV-01
A16: SRS-D09b | B16: Hằng số T_i,I PI dòng | C16: ='Tính chọn'!$D$129 | D16: s | E16: SRS-FUNC-01 (Downstream #4) | F16: Tính chọn K | G16: S | H16: DV-01
A17: SRS-D10 | B17: Mô-men giữ thử (phanh còn kẹp) trước khi nhả phanh (100% M_N, trong [100; 150]%) | C17: ='Tính chọn'!$D$87 | D17: N·m | E17: SRS-FUNC-02 (Downstream #5) | F17: SDD §5 (FSM) | G17: S | H17: DV-02
A18: SRS-D11a | B18: Ngưỡng đóng phanh |v| | C18: =GiaDinh_K3!$D$31 | D18: m/s | E18: SRS-FUNC-02 (Downstream #5) | F18: SDD §5 | G18: S | H18: DV-02
A19: SRS-D11b | B19: Ngưỡng cấm đảo chiều |v| | C19: =GiaDinh_K3!$D$32 | D19: m/s | E19: SRS-FUNC-02 (Downstream #5) | F19: SDD §5 | G19: S | H19: DV-02
A20: SRS-D12 | B20: Tốc độ bò v_creep | C20: ='Tính chọn'!$D$172 | D20: m/s | E20: SRS-FUNC-03 (Downstream #8) | F20: Tính chọn N | G20: S | H20: DV-06
A21: SRS-D13 | B21: Mô-men phanh đặt M_B (cửa sổ [max(k_p M_c; 1.2 M_hold); M_B,max]) | C21: =GiaDinh_K3!$D$20 | D21: N·m | E21: SRS-FUNC-02 | F21: Tính chọn I | G21: A / I | H21: DV-02
A22: SRS-D14 | B22: Tỷ số từ thông ψ_r*/ψ_rN tại v_max khi lưới −10% (giảm từ thông theo giới hạn điện áp) | C22: ='Tính chọn'!$D$199 | D22: - | E22: SRS-PERM-02 | F22: Tính chọn P | G22: S | H22: DV-06
A23: SRS-D15 | B23: Tốc độ ĐC bắt đầu giảm từ thông ω_fw (lưới danh định; mô phỏng tính trực tuyến theo U_dc đo) | C23: ='Tính chọn'!$D$200 | D23: rad/s | E23: SRS-PERM-02 | F23: Tính chọn P | G23: S | H23: DV-06

Sheet Mo_phong
A1: Nhóm | B1: Tên biến (ICD v1.2 §4.1) | C1: Giá trị | D1: Đơn vị | E1: Ô nguồn | F1: Ghi chú
A2: Cơ | B2: M_full | C2: =Params!$C$5 | D2: kg | E2: Params!C5 | F2: Chỉ dùng cho tính lực cản F_c
A3: Cơ | B3: M_empty | C3: =Params!$C$6 | D3: kg | E3: Params!C6 | F3: Chỉ dùng cho tính lực cản F_c,0
A4: Cơ | B4: m_trolley | C4: ='Tính chọn'!$D$175 | D4: kg | E4: Tính chọn O | F4: Khối lượng cứng của mô hình 2 khối
A5: Cơ | B5: m_pend_full | C5: ='Tính chọn'!$D$176 | D5: kg | E5: Tính chọn O | F5: Q + m_nh
A6: Cơ | B6: m_pend_empty | C6: ='Tính chọn'!$D$177 | D6: kg | E6: Tính chọn O | F6: m_nh
A7: Cơ | B7: D_bx | C7: =Params!$C$13 | D7: m | E7: Params!C13
A8: Cơ | B8: w0 | C8: =Params!$C$14 | D8: - | E8: Params!C14
A9: Cơ | B9: phi | C9: =Params!$C$15 | D9: - | E9: Params!C15
A10: Cơ | B10: eta | C10: =Params!$C$16 | D10: - | E10: Params!C16
A11: Cơ | B11: g | C11: =Params!$C$19 | D11: m/s² | E11: Params!C19
A12: Cơ | B12: h | C12: =Params!$C$7 | D12: m | E12: Params!C7
A13: Cơ | B13: k_qd | C13: ='Tính chọn'!$D$23 | D13: m/rad | E13: Tính chọn C
A14: Cơ | B14: i_gear | C14: ='Tính chọn'!$D$20 | D14: - | E14: Tính chọn C | F14: SEW R87
A15: Cơ | B15: delta | C15: =GiaDinh_K3!$D$8 | D15: - | E15: GiaDinh_K3 | F15: Chỉ cho tính khối cứng (Excel)
A16: Cơ | B16: J_gear | C16: ='Tính chọn'!$D$178 | D16: kg·m² | E16: Tính chọn O | F16: (δ−1)·M_Σ·k²
A17: Cơ | B17: J_rig | C17: ='Tính chọn'!$D$179 | D17: kg·m² | E17: Tính chọn O | F17: Quán tính cứng trên trục ĐC
A18: Cơ | B18: zeta | C18: =GiaDinh_K3!$D$45 | D18: - | E18: GiaDinh_K3
A19: Cơ | B19: mech_model | C19: =GiaDinh_K3!$D$58 | D19: - | E19: GiaDinh_K3 | F19: 0 = 2 khối lượng; 1 = khối cứng (DV-04 bảo thủ)
A20: Động cơ | B20: Rs | C20: ='Tính chọn'!$D$109 | D20: Ω | E20: Tính chọn J
A21: Động cơ | B21: Rr | C21: ='Tính chọn'!$D$104 | D21: Ω | E21: Tính chọn J
A22: Động cơ | B22: Lls | C22: ='Tính chọn'!$D$111 | D22: H | E22: Tính chọn J
A23: Động cơ | B23: Llr | C23: ='Tính chọn'!$D$112 | D23: H | E23: Tính chọn J
A24: Động cơ | B24: Lm | C24: ='Tính chọn'!$D$110 | D24: H | E24: Tính chọn J
A25: Động cơ | B25: pp | C25: =GiaDinh_K3!$D$28 | D25: - | E25: GiaDinh_K3
A26: Động cơ | B26: J_Bmot | C26: =Catalogue!$F$15 | D26: kg·m² | E26: Catalogue | F26: Rotor kèm phanh
A27: Động cơ | B27: psi_rN | C27: ='Tính chọn'!$D$122 | D27: Wb | E27: Tính chọn J
A28: Động cơ | B28: U_N | C28: =GiaDinh_K3!$D$29 | D28: V | E28: GiaDinh_K3
A29: Động cơ | B29: f_N | C29: =GiaDinh_K3!$D$6 | D29: Hz | E29: GiaDinh_K3
A30: Biến tần | B30: U_grid | C30: =Params!$C$20 | D30: V | E30: Params!C20 | F30: Chạy thêm U_grid·(1 ± dU_grid)
A31: Biến tần | B31: dU_grid | C31: =GiaDinh_K3!$D$5 | D31: - | E31: GiaDinh_K3
A32: Biến tần | B32: f_sw | C32: =GiaDinh_K3!$D$22 | D32: Hz | E32: GiaDinh_K3 | F32: Chỉ để tính Ts_I (mô hình trung bình)
A33: Biến tần | B33: k_u | C33: =GiaDinh_K3!$D$44 | D33: - | E33: GiaDinh_K3 | F33: |u_s| ≤ k_u·U_dc/√3 (biên độ pha)
A34: Biến tần | B34: C_dc | C34: =GiaDinh_K3!$D$46 | D34: F | E34: GiaDinh_K3 | F34: Chưa xác minh
A35: Biến tần | B35: R_src | C35: ='Tính chọn'!$D$212 | D35: Ω | E35: Tính chọn Q
A36: Biến tần | B36: Udc_chop_on | C36: =GiaDinh_K3!$D$14 | D36: V | E36: GiaDinh_K3
A37: Biến tần | B37: Udc_chop_off | C37: ='Tính chọn'!$D$215 | D37: V | E37: Tính chọn Q
A38: Biến tần | B38: Udc_max | C38: =GiaDinh_K3!$D$15 | D38: V | E38: GiaDinh_K3
A39: Biến tần | B39: Udc_trip | C39: =GiaDinh_K3!$D$16 | D39: V | E39: GiaDinh_K3
A40: Biến tần | B40: Rh | C40: =GiaDinh_K3!$D$42 | D40: Ω | E40: GiaDinh_K3
...

Sheet WCCA
A1: Đại lượng | B1: WC-0 Danh định | C1: WC-1 Lưới −10% | D1: WC-2 w0 = 0.018 | E1: WC-3 m_xc +20% | F1: WC-4 η = 0.85 | G1: WC-5 Tổ hợp kéo | H1: WC-6 φ = 0.15 | I1: WC-7 Tổ hợp hãm | J1: Công thức / Ghi chú
A2: m_xc (kg) | B2: 1800 | C2: 1800 | D2: 1800 | E2: 2160 | F2: 1800 | G2: 2160 | H2: 1800 | I2: 1800 | J2: Biến thiên P-03 [C]
A3: w_0 (-) | B3: 0.015 | C3: 0.015 | D3: 0.018 | E3: 0.015 | F3: 0.015 | G3: 0.018 | H3: 0.015 | I3: 0.012 | J3: Dải SOW 0.012–0.018
A4: η (-) | B4: 0.9 | C4: 0.9 | D4: 0.9 | E4: 0.9 | F4: 0.85 | G4: 0.85 | H4: 0.9 | I4: 0.95 | J4: Biến thiên P-15 [C]
A5: ΔU lưới (-) | B5: 0 | C5: -0.1 | D5: 0 | E5: 0 | F5: 0 | G5: -0.1 | H5: 0 | I5: 0.1 | J5: P-19: ±10%
A6: φ (-) | B6: 0.2 | C6: 0.2 | D6: 0.2 | E6: 0.2 | F6: 0.2 | G6: 0.2 | H6: 0.15 | I6: 0.2 | J6: Độ nhạy P-14 [C]
A7: M_Σ (kg) | B7: =Params!$C$2+Params!$C$3+B2 | C7: =Params!$C$2+Params!$C$3+C2 | D7: =Params!$C$2+Params!$C$3+D2 | E7: =Params!$C$2+Params!$C$3+E2 | F7: =Params!$C$2+Params!$C$3+F2 | G7: =Params!$C$2+Params!$C$3+G2 | H7: =Params!$C$2+Params!$C$3+H2 | I7: =Params!$C$2+Params!$C$3+I2 | J7: Q + m_nh + m_xc
A8: F_c (N) | B8: =B7*Params!$C$19*B3 | C8: =C7*Params!$C$19*C3 | D8: =D7*Params!$C$19*D3 | E8: =E7*Params!$C$19*E3 | F8: =F7*Params!$C$19*F3 | G8: =G7*Params!$C$19*G3 | H8: =H7*Params!$C$19*H3 | I8: =I7*Params!$C$19*I3 | J8: M_Σ·g·w_0
A9: M_max (N·m) tại a_max | B9: =(B8+GiaDinh_K3!$D$8*B7*Params!$C$11)*'Tính chọn'!$D$23/B4+Catalogue!$F$15*Params!$C$11/'Tính chọn'!$D$23 | C9: =(C8+GiaDinh_K3!$D$8*C7*Params!$C$11)*'Tính chọn'!$D$23/C4+Catalogue!$F$15*Params!$C$11/'Tính chọn'!$D$23 | D9: =(D8+GiaDinh_K3!$D$8*D7*Params!$C$11)*'Tính chọn'!$D$23/D4+Catalogue!$F$15*Params!$C$11/'Tính chọn'!$D$23 | E9: =(E8+GiaDinh_K3!$D$8*E7*Params!$C$11)*'Tính chọn'!$D$23/E4+Catalogue!$F$15*Params!$C$11/'Tính chọn'!$D$23 | F9: =(F8+GiaDinh_K3!$D$8*F7*Params!$C$11)*'Tính chọn'!$D$23/F4+Catalogue!$F$15*Params!$C$11/'Tính chọn'!$D$23 | G9: =(G8+GiaDinh_K3!$D$8*G7*Params!$C$11)*'Tính chọn'!$D$23/G4+Catalogue!$F$15*Params!$C$11/'Tính chọn'!$D$23 | H9: =(H8+GiaDinh_K3!$D$8*H7*Params!$C$11)*'Tính chọn'!$D$23/H4+Catalogue!$F$15*Params!$C$11/'Tính chọn'!$D$23 | I9: =(I8+GiaDinh_K3!$D$8*I7*Params!$C$11)*'Tính chọn'!$D$23/I4+Catalogue!$F$15*Params!$C$11/'Tính chọn'!$D$23 | J9: Như 'Tính chọn' D
A10: M_max/M_N | B10: =B9/Catalogue!$F$5 | C10: =C9/Catalogue!$F$5 | D10: =D9/Catalogue!$F$5 | E10: =E9/Catalogue!$F$5 | F10: =F9/Catalogue!$F$5 | G10: =G9/Catalogue!$F$5 | H10: =H9/Catalogue!$F$5 | I10: =I9/Catalogue!$F$5
A11: λ khả dụng | B11: =Catalogue!$F$12*(Params!$C$20*(1+B5)/GiaDinh_K3!$D$29)^2 | C11: =Catalogue!$F$12*(Params!$C$20*(1+C5)/GiaDinh_K3!$D$29)^2 | D11: =Catalogue!$F$12*(Params!$C$20*(1+D5)/GiaDinh_K3!$D$29)^2 | E11: =Catalogue!$F$12*(Params!$C$20*(1+E5)/GiaDinh_K3!$D$29)^2 | F11: =Catalogue!$F$12*(Params!$C$20*(1+F5)/GiaDinh_K3!$D$29)^2 | G11: =Catalogue!$F$12*(Params!$C$20*(1+G5)/GiaDinh_K3!$D$29)^2 | H11: =Catalogue!$F$12*(Params!$C$20*(1+H5)/GiaDinh_K3!$D$29)^2 | I11: =Catalogue!$F$12*(Params!$C$20*(1+I5)/GiaDinh_K3!$D$29)^2 | J11: λ_K·(U/U_N)², U_N = 400 V
A12: Biên quá tải | B12: =B11/B10 | C12: =C11/C10 | D12: =D11/D10 | E12: =E11/E10 | F12: =F11/F10 | G12: =G11/G10 | H12: =H11/H10 | I12: =I11/I10 | J12: Phải ≥ 1
A13: k_bám tại a_max | B13: =B6*GiaDinh_K3!$D$9*B7*Params!$C$19/(B8+B7*Params!$C$11) | C13: =C6*GiaDinh_K3!$D$9*C7*Params!$C$19/(C8+C7*Params!$C$11) | D13: =D6*GiaDinh_K3!$D$9*D7*Params!$C$19/(D8+D7*Params!$C$11) | E13: =E6*GiaDinh_K3!$D$9*E7*Params!$C$19/(E8+E7*Params!$C$11) | F13: =F6*GiaDinh_K3!$D$9*F7*Params!$C$19/(F8+F7*Params!$C$11) | G13: =G6*GiaDinh_K3!$D$9*G7*Params!$C$19/(G8+G7*Params!$C$11) | H13: =H6*GiaDinh_K3!$D$9*H7*Params!$C$19/(H8+H7*Params!$C$11) | I13: =I6*GiaDinh_K3!$D$9*I7*Params!$C$19/(I8+I7*Params!$C$11) | J13: Tham khảo
A14: k_bám tại a* (quỹ đạo thật) | B14: =B6*GiaDinh_K3!$D$9*B7*Params!$C$19/(B8+B7*GiaDinh_K3!$D$11) | C14: =C6*GiaDinh_K3!$D$9*C7*Params!$C$19/(C8+C7*GiaDinh_K3!$D$11) | D14: =D6*GiaDinh_K3!$D$9*D7*Params!$C$19/(D8+D7*GiaDinh_K3!$D$11) | E14: =E6*GiaDinh_K3!$D$9*E7*Params!$C$19/(E8+E7*GiaDinh_K3!$D$11) | F14: =F6*GiaDinh_K3!$D$9*F7*Params!$C$19/(F8+F7*GiaDinh_K3!$D$11) | G14: =G6*GiaDinh_K3!$D$9*G7*Params!$C$19/(G8+G7*GiaDinh_K3!$D$11) | H14: =H6*GiaDinh_K3!$D$9*H7*Params!$C$19/(H8+H7*GiaDinh_K3!$D$11) | I14: =I6*GiaDinh_K3!$D$9*I7*Params!$C$19/(I8+I7*GiaDinh_K3!$D$11) | J14: Phải ≥ 1.20
A15: P_dc,hãm (W) | B15: =(B7*Params!$C$11-B8)*Params!$C$10*B4*Catalogue!$F$9*GiaDinh_K3!$D$13 | C15: =(C7*Params!$C$11-C8)*Params!$C$10*C4*Catalogue!$F$9*GiaDinh_K3!$D$13 | D15: =(D7*Params!$C$11-D8)*Params!$C$10*D4*Catalogue!$F$9*GiaDinh_K3!$D$13 | E15: =(E7*Params!$C$11-E8)*Params!$C$10*E4*Catalogue!$F$9*GiaDinh_K3!$D$13 | F15: =(F7*Params!$C$11-F8)*Params!$C$10*F4*Catalogue!$F$9*GiaDinh_K3!$D$13 | G15: =(G7*Params!$C$11-G8)*Params!$C$10*G4*Catalogue!$F$9*GiaDinh_K3!$D$13 | H15: =(H7*Params!$C$11-H8)*Params!$C$10*H4*Catalogue!$F$9*GiaDinh_K3!$D$13 | I15: =(I7*Params!$C$11-I8)*Params!$C$10*I4*Catalogue!$F$9*GiaDinh_K3!$D$13 | J15: Phải ≤ P_BRmax
A16: U_dc0 không tải (V) | B16: =SQRT(2)*Params!$C$20*(1+B5) | C16: =SQRT(2)*Params!$C$20*(1+C5) | D16: =SQRT(2)*Params!$C$20*(1+D5) | E16: =SQRT(2)*Params!$C$20*(1+E5) | F16: =SQRT(2)*Params!$C$20*(1+F5) | G16: =SQRT(2)*Params!$C$20*(1+G5) | H16: =SQRT(2)*Params!$C$20*(1+H5) | I16: =SQRT(2)*Params!$C$20*(1+I5) | J16: Phải < U_chop − 20 V
A17: k_dt ước lượng | B17: ='Tính chọn'!$D$60*Params!$C$21/B8*MIN(1,Params!$C$20*(1+B5)/GiaDinh_K3!$D$29) | C17: ='Tính chọn'!$D$60*Params!$C$21/C8*MIN(1,Params!$C$20*(1+C5)/GiaDinh_K3!$D$29) | D17: ='Tính chọn'!$D$60*Params!$C$21/D8*MIN(1,Params!$C$20*(1+D5)/GiaDinh_K3!$D$29) | E17: ='Tính chọn'!$D$60*Params!$C$21/E8*MIN(1,Params!$C$20*(1+E5)/GiaDinh_K3!$D$29) | F17: ='Tính chọn'!$D$60*Params!$C$21/F8*MIN(1,Params!$C$20*(1+F5)/GiaDinh_K3!$D$29) | G17: ='Tính chọn'!$D$60*Params!$C$21/G8*MIN(1,Params!$C$20*(1+G5)/GiaDinh_K3!$D$29) | H17: ='Tính chọn'!$D$60*Params!$C$21/H8*MIN(1,Params!$C$20*(1+H5)/GiaDinh_K3!$D$29) | I17: ='Tính chọn'!$D$60*Params!$C$21/I8*MIN(1,Params!$C$20*(1+I5)/GiaDinh_K3!$D$29) | J17: Gần đúng: M_đt ∝ F_c; dòng ∝ 1/U khi gần tốc độ định mức
A18: Kết luận | B18: =IF(AND(B12>=1,B14>=1.2,B15/1000<=Catalogue!$F$27,B16<GiaDinh_K3!$D$14-20,B17>=1.2),"Đạt","Xem lại") | C18: =IF(AND(C12>=1,C14>=1.2,C15/1000<=Catalogue!$F$27,C16<GiaDinh_K3!$D$14-20,C17>=1.2),"Đạt","Xem lại") | D18: =IF(AND(D12>=1,D14>=1.2,D15/1000<=Catalogue!$F$27,D16<GiaDinh_K3!$D$14-20,D17>=1.2),"Đạt","Xem lại") | E18: =IF(AND(E12>=1,E14>=1.2,E15/1000<=Catalogue!$F$27,E16<GiaDinh_K3!$D$14-20,E17>=1.2),"Đạt","Xem lại") | F18: =IF(AND(F12>=1,F14>=1.2,F15/1000<=Catalogue!$F$27,F16<GiaDinh_K3!$D$14-20,F17>=1.2),"Đạt","Xem lại") | G18: =IF(AND(G12>=1,G14>=1.2,G15/1000<=Catalogue!$F$27,G16<GiaDinh_K3!$D$14-20,G17>=1.2),"Đạt","Xem lại") | H18: =IF(AND(H12>=1,H14>=1.2,H15/1000<=Catalogue!$F$27,H16<GiaDinh_K3!$D$14-20,H17>=1.2),"Đạt","Xem lại") | I18: =IF(AND(I12>=1,I14>=1.2,I15/1000<=Catalogue!$F$27,I16<GiaDinh_K3!$D$14-20,I17>=1.2),"Đạt","Xem lại") | J18: Tổng hợp
