Workbook

Sheet Info
A1: TÍNH TOÁN CHỌN ĐỘNG CƠ, BIẾN TẦN, R_h — XE CON CẦU TRỤC DẦM ĐÔI (x = 2) — BẢN RÚT GỌN v2.0
A2: Ngày lập: 28/10/2026. Áp dụng CR-19 (nhật ký: Block 3/04_SRS_A1_Dan_xuat_RTM_DVP_WCCA_v1.0.md §1). Bản v1.5 giữ nguyên làm lịch sử.
A3: Mục đích: chỉ giữ chuỗi tính phục vụ chọn thiết bị: phụ tải → quy đổi → chọn động cơ (nhiệt + quá tải) → 14 tham số động cơ + hiệu chỉnh → biến tần, R_h, phanh.
A4: Phần thiết kế bộ điều khiển PI, mô hình 2 khối lượng, DC-link, giảm từ thông, kịch bản mô phỏng, WCCA: để ở khối điều khiển/mô phỏng (xem v1.5).
A6: Thứ tự đọc các sheet:
A7: 1. Params — số liệu đề bài [A], tính toán [B], giả định nhóm [C] (ô nền vàng = ô nhập).
A8: 2. Catalogue — số liệu động cơ SEW DRN.., biến tần ABB ACS380, phanh BE, hộp số, R_h (nguồn [W-xx]).
A9: 3. Phu_tai — lực cản, quy đổi về trục động cơ, quỹ đạo S-curve, chu trình S3-40%, đồ thị phụ tải.
A10: 4. Chon_DC — so sánh 4 động cơ ứng viên và ảnh hưởng của gia tốc đặt a* tới cỡ động cơ.
A11: 5. Tham_so_DC — 14 công thức (Class_3_AC_Motor_Drive slide 9–11), bộ hiệu chỉnh, kiểm chứng với catalogue.
A12: 6. Thiet_bi — biến tần, điện trở hãm R_h, phanh cơ, hộp số, cầu chì.
A13: 7. Kiem_tra — tổng hợp các điều kiện ĐẠT / KHÔNG ĐẠT.
A15: Ký hiệu nguồn: [A] đề bài; [B] tính từ [A]; [C] giả định nhóm. [W-xx]: Tài liệu tham khảo/Catalogue web/. [R..]: Tài liệu tham khảo/00_Danh_muc_tai_lieu_tham_khao.md.

Sheet Params
A1: Mã | B1: Đại lượng | C1: Ký hiệu | D1: Giá trị | E1: Đơn vị | F1: Công thức / Ghi chú | G1: Nguồn | H1: Loại
A2: A. Thông số gốc SSoT P-01..P-20 (Block 1/00_Bang_thong_so_goc_SSoT.md)
A3: Q | B3: Tải trọng nâng định mức (P-01) | C3: Q | D3: 12222 | E3: kg | G3: Đề bài x = 2 | H3: [A]
A4: mnh | B4: Khối lượng cơ cấu nâng hạ (P-02) | C4: m_nh | D4: 222 | E4: kg | G4: Đề bài x = 2 | H4: [A]
A5: mxc | B5: Khối lượng xe con (P-03) | C5: m_xc | D5: 1800 | E5: kg | F5: ≈ 15% Q | G5: SSoT P-03 | H5: [C]
A6: M | B6: Tổng khối lượng đầy tải (P-04) | C6: M_Σ | D6: =Params!$D$3+Params!$D$4+Params!$D$5 | E6: kg | F6: Q + m_nh + m_xc | H6: [B]
A7: m0 | B7: Tổng khối lượng không tải (P-05) | C7: m_0 | D7: =Params!$D$4+Params!$D$5 | E7: kg | F7: m_nh + m_xc | H7: [B]
A8: h | B8: Chiều dài cáp lớn nhất (P-06) | C8: h | D8: 12 | E8: m | G8: Đề bài x = 2 | H8: [A]
A9: g | B9: Gia tốc trọng trường (P-18) | C9: g | D9: 9.81 | E9: m/s² | H9: [C]
A10: wp | B10: Tần số góc con lắc (P-07) | C10: ω_p | D10: =SQRT(Params!$D$9/Params!$D$8) | E10: rad/s | F10: √(g/h) | H10: [B]
A11: Tp | B11: Chu kỳ con lắc (P-08) | C11: T_p | D11: =2*PI()/Params!$D$10 | E11: s | F11: 2π/ω_p | H11: [B]
A12: v | B12: Vận tốc di chuyển lớn nhất (P-09) | C12: v_max | D12: 0.12 | E12: m/s | F12: Dung sai nghiệm thu ±5% (SRS-PERM-02) | G12: Đề bài x = 2 | H12: [A]
A13: amax | B13: Gia tốc cho phép lớn nhất (P-10) | C13: a_max | D13: 0.5 | E13: m/s² | F13: Giới hạn trên (CR-09) | G13: Đề bài | H13: [A]
A14: rmax | B14: Độ giật cho phép lớn nhất (P-11) | C14: ρ_max | D14: 2 | E14: m/s³ | F14: Giới hạn trên (CR-09) | G14: Đề bài | H14: [A]
A15: D | B15: Đường kính bánh xe (P-12) | C15: D_bx | D15: 0.25 | E15: m | G15: SSoT P-12 | H15: [C]
A16: w0 | B16: Suất cản lăn (P-13) | C16: w_0 | D16: 0.015 | E16: - | F16: Tính kiểm 0.013–0.018 (SSoT Phần 1b) | G16: SSoT P-13 | H16: [C]
A17: phi | B17: Hệ số bám bánh thép/ray (P-14) | C17: φ | D17: 0.2 | E17: - | G17: SSoT P-14 | H17: [C]
A18: eta | B18: Hiệu suất cơ khí (P-15) | C18: η | D18: 0.9 | E18: - | G18: SSoT P-15 | H18: [C]
A19: CD | B19: Hệ số đóng điện S3 (P-17) | C19: CD | D19: 0.4 | E19: - | F19: S3-40% | G19: IEC 60034-1 [R4] tr.23 | H19: [C]
A20: Tck | B20: Chu kỳ chuẩn S3 (P-17) | C20: T_ck | D20: 600 | E20: s | F20: 10 phút | G20: IEC 60034-1 [R4] tr.23 | H20: [C]
A21: U | B21: Điện áp lưới danh định (P-19) | C21: U_lưới | D21: 380 | E21: V | F21: Dao động ±10% | G21: SSoT P-19 | H21: [C]
A22: dU | B22: Dao động điện áp lưới (P-19) | C22: ΔU | D22: 0.1 | E22: - | G22: SSoT P-19 | H22: [C]
A23: f | B23: Tần số lưới (P-19) | C23: f | D23: 50 | E23: Hz | G23: SSoT P-19 | H23: [C]
A24: Fc | B24: Lực cản tĩnh đầy tải (P-20) | C24: F_c | D24: =Params!$D$6*Params!$D$9*Params!$D$16 | E24: N | F24: M_Σ·g·w_0 | H24: [B]
A25: B. Giả định thiết kế [C] — lượng đặt quỹ đạo theo CR-19
A26: aset | B26: Gia tốc đặt S-curve (CR-19) | C26: a* | D26: 0.1 | E26: m/s² | F26: Chọn trong giới hạn a ≤ a_max. Lý do: sheet Chon_DC mục B; CR-19 | G26: CR-19 | H26: [C]
A27: rset | B27: Độ giật đặt S-curve (CR-19) | C27: ρ* | D27: 0.4 | E27: m/s³ | F27: ρ*/a* = 4 s⁻¹ ⇒ đoạn tăng/giảm độ giật T_j = 0.25 s như bản cũ | G27: CR-19 | H27: [C]
A28: delta | B28: Hệ số kể quán tính hộp số, khớp nối | C28: δ | D28: 1.15 | E28: - | F28: Quán tính động cơ + phanh J_B cộng riêng (không tính trùng) | G28: WORKFLOW §4.2-B4 | H28: [C]
A29: kdan | B29: Tỷ lệ trọng lượng trên bánh dẫn | C29: k_dẫn | D29: 0.5 | E29: - | F29: 2/4 bánh dẫn (SAD TO-02) | G29: SAD §3.2 | H29: [C]
A30: nht | B30: Số hành trình mỗi chu kỳ S3 | C30: n_ht | D30: 2 | E30: - | F30: 1 đầy tải (Tiến) + 1 không tải (Lùi) | G30: SSoT Phần 1b | H30: [C]
A31: kbmin | B31: Hệ số an toàn bám tối thiểu | C31: k_bám,min | D31: 1.2 | E31: - | F31: SRS-PERM-01 | G31: SRS-PERM-01 | H31: [C]
A32: kdtmin | B32: Hệ số dự trữ nhiệt tối thiểu | C32: k_dt,min | D32: 1.2 | E32: - | F32: SRS-PERM-04 (SRS A.1) | G32: SRS-PERM-04 | H32: [C]
A33: klam | B33: Hệ số dự trữ quá tải mô-men tối thiểu | C33: k_λ,min | D33: 1.2 | E33: - | F33: M_max ≤ λ_K(U_min/U_N)²·M_N / 1.2 | G33: Giả định nhóm | H33: [C]
A34: UN | B34: Điện áp định mức động cơ | C34: U_N | D34: 400 | E34: V | F34: Động cơ DRN 400 V/50 Hz | G34: [W-01] | H34: [C]
A35: pp | B35: Số đôi cực | C35: p | D35: 2 | E35: - | F35: Động cơ 4 cực | G35: [W-01] | H35: [C]
A36: einv | B36: Hiệu suất biến tần | C36: η_inv | D36: 0.97 | E36: - | F36: Giá trị điển hình | G36: Giả định | H36: [C]
A37: kp | B37: Hệ số an toàn phanh giữ | C37: k_p | D37: 1.25 | E37: - | G37: TCVN 4244 §1.5.3.3 [R1] | H37: [C]
A38: khold | B38: Mô-men thử trước khi nhả phanh (bội số M_N) | C38: M_hold/M_N | D38: 1 | E38: - | G38: SDD §5 | H38: [C]
A39: ktest | B39: Hệ số dự trữ phanh khi thử mô-men | C39: k_thử | D39: 1.2 | E39: - | G39: SDD §5 | H39: [C]
A40: kfe | B40: Tỷ lệ tổn hao sắt + cơ + phụ trong tổng tổn hao | C40: k_Fe | D40: 0.3 | E40: - | F40: Dùng tách R_s từ cân bằng công suất | G40: Giả định | H40: [C]
...

Sheet Catalogue
A1: Mã | B1: Thông số | C1: Ký hiệu | D1: Ứng viên 1 | E1: Ứng viên 2 | F1: Ứng viên 3 | G1: Ứng viên 4 | H1: Đang chọn | I1: Đơn vị | J1: Nguồn
A2: Ô chọn thiết bị (nhập số thứ tự cột ứng viên)
A3: sel_mot | B3: Động cơ đang chọn (1..4) | D3: 2 | J3: 2 = DRN71M4 (kết quả sheet Chon_DC)
A4: sel_inv | B4: Biến tần đang chọn (1..3) | D4: 1 | J4: 1 = ACS380-04xS-01A8-4 (kết quả sheet Thiet_bi)
A5: Động cơ SEW DRN.. IE3, 400 V, 50 Hz, 4 cực, S1 — [W-01] tr.866
A6: mname | B6: Mã động cơ | D6: DRN71MS4 | E6: DRN71M4 | F6: DRN80MK4 | G6: DRN80M4 | H6: =INDEX($D$6:$G$6,Catalogue!$D$3) | J6: [W-01] tr.866
A7: PN | B7: Công suất định mức | C7: P_N | D7: 0.25 | E7: 0.37 | F7: 0.55 | G7: 0.75 | H7: =INDEX($D$7:$G$7,Catalogue!$D$3) | I7: kW | J7: [W-01] tr.866
A8: MN | B8: Mô-men định mức | C8: M_N | D8: 1.7 | E8: 2.5 | F8: 3.65 | G8: 4.95 | H8: =INDEX($D$8:$G$8,Catalogue!$D$3) | I8: N·m | J8: [W-01] tr.866
A9: nN | B9: Tốc độ định mức | C9: n_N | D9: 1405 | E9: 1415 | F9: 1435 | G9: 1440 | H9: =INDEX($D$9:$G$9,Catalogue!$D$3) | I9: vg/ph | J9: [W-01] tr.866
A10: IN | B10: Dòng định mức (400 V) | C10: I_N | D10: 0.72 | E10: 1.02 | F10: 1.29 | G10: 1.75 | H10: =INDEX($D$10:$G$10,Catalogue!$D$3) | I10: A | J10: [W-01] tr.866
A11: cos | B11: Hệ số công suất | C11: cosφ_N | D11: 0.66 | E11: 0.66 | F11: 0.75 | G11: 0.74 | H11: =INDEX($D$11:$G$11,Catalogue!$D$3) | I11: - | J11: [W-01] tr.866
A12: eff | B12: Hiệu suất 100% tải | C12: η_đc | D12: 0.735 | E12: 0.773 | F12: 0.808 | G12: 0.829 | H12: =INDEX($D$12:$G$12,Catalogue!$D$3) | I12: - | J12: [W-01] tr.866
A13: MA | B13: Bội số mô-men khởi động | C13: M_A/M_N | D13: 2.5 | E13: 2.8 | F13: 2.7 | G13: 3.1 | H13: =INDEX($D$13:$G$13,Catalogue!$D$3) | I13: - | J13: [W-01] tr.866
A14: lamK | B14: Bội số mô-men tới hạn | C14: λ_K | D14: 2.5 | E14: 2.8 | F14: 3.1 | G14: 3.4 | H14: =INDEX($D$14:$G$14,Catalogue!$D$3) | I14: - | J14: [W-01] tr.866
A15: JB | B15: Quán tính rotor kèm phanh | C15: J_BMot | D15: 0.00262 | E15: 0.00262 | F15: 0.00262 | G15: 0.00262 | H15: =INDEX($D$15:$G$15,Catalogue!$D$3) | I15: kg·m² | J15: DRN80M4: 26.2×10⁻⁴ [W-02] tr.25. Khung DRN71/80MK chưa có số trong kho → lấy bằng DRN80M4 làm cận trên [C] (bảo thủ; ảnh hưởng < 0.33 N·m tại a* = 0.1)
A16: Biến tần ABB ACS380, 3 pha 400 V — [W-05] tr.12 (định mức), tr.24 (chopper); [W-08] (cầu chì)
A17: iname | B17: Mã biến tần | D17: ACS380-04xS-01A8-4 | E17: ACS380-04xS-02A6-4 | F17: ACS380-04xS-03A3-4 | H17: =INDEX($D$17:$F$17,Catalogue!$D$4) | J17: [W-05] tr.12
A18: IinvN | B18: Dòng định mức | C18: I_N,inv | D18: 1.8 | E18: 2.6 | F18: 3.3 | H18: =INDEX($D$18:$F$18,Catalogue!$D$4) | I18: A | J18: [W-05] tr.12
A19: IHd | B19: Dòng heavy-duty (cho phép 150% trong 1 phút/10 phút) | C19: I_Hd | D19: 1.2 | E19: 1.8 | F19: 2.6 | H19: =INDEX($D$19:$F$19,Catalogue!$D$4) | I19: A | J19: [W-05] tr.12
A20: PHd | B20: Công suất heavy-duty | C20: P_Hd | D20: 0.37 | E20: 0.55 | F20: 0.75 | H20: =INDEX($D$20:$F$20,Catalogue!$D$4) | I20: kW | J20: [W-05] tr.12
A21: Imax | B21: Dòng ra cực đại | C21: I_max | D21: 2.2 | E21: 3.2 | F21: 4.7 | H21: =INDEX($D$21:$F$21,Catalogue!$D$4) | I21: A | J21: [W-05] tr.12
A22: Rmin | B22: Điện trở hãm tối thiểu | C22: R_min | D22: 99 | E22: 99 | F22: 99 | H22: =INDEX($D$22:$F$22,Catalogue!$D$4) | I22: Ω | J22: [W-05] tr.24
A23: Rmax | B23: Điện trở hãm tối đa cho P_BRcont | C23: R_max | D23: 933 | E23: 628 | F23: 428 | H23: =INDEX($D$23:$F$23,Catalogue!$D$4) | I23: Ω | J23: [W-05] tr.24
A24: PBRc | B24: Công suất hãm liên tục | C24: P_BRcont | D24: 0.37 | E24: 0.55 | F24: 0.75 | H24: =INDEX($D$24:$F$24,Catalogue!$D$4) | I24: kW | J24: [W-05] tr.24
A25: PBRm | B25: Công suất hãm cực đại (xung ≤ 1 phút/10 phút) | C25: P_BRmax | D25: 0.56 | E25: 0.83 | F25: 1.13 | H25: =INDEX($D$25:$F$25,Catalogue!$D$4) | I25: kW | J25: [W-05] tr.24
A26: fuse | B26: Cầu chì gG khuyến nghị | D26: OFAF000H4 (4 A) | E26: OFAF000H6 (6 A) | F26: OFAF000H6 (6 A) | H26: =INDEX($D$26:$F$26,Catalogue!$D$4) | J26: [W-08]; cáp 3×1.5 + 1.5 mm²
A27: Phanh, hộp số, điện trở hãm
A28: BE1 | B28: Các cấp mô-men phanh BE1 (lắp được cho DR71/80/90) | C28: M_B | D28: 5 | E28: 7 | F28: 10 | I28: N·m | J28: [W-07] SEW B-107-04
A29: MBsel | B29: Mô-men phanh chọn | C29: M_B | D29: 5 | I29: N·m | J29: BE1, 3 lò xo thường [W-07]
A30: Mamax | B30: Mô-men ra cho phép lớn nhất hộp số R87 | C30: M_a,max | D30: 1550 | I30: N·m | J30: [W-06]
A31: Rh | B31: Điện trở hãm Danotherm CBH 360 C T 406 210R | C31: R_h | D31: 210 | I31: Ω | J31: [W-05] tr.24 (điện trở mẫu cho 01A8..03A3); [W-09]
A32: PRh | B32: Công suất định mức điện trở hãm (40 °C) | C32: P_Rh | D32: 200 | I32: W | J32: [W-09]

Sheet Phu_tai
A1: Mã | B1: Đại lượng | C1: Ký hiệu | D1: Giá trị | E1: Đơn vị | F1: Công thức / Ghi chú | G1: Nguồn | I1: t (s) | J1: a (m/s²) | K1: v (m/s) | L1: M đầy tải (N·m) | M1: M không tải (N·m)
A2: A. Động học và phụ tải tĩnh | I2: 0 | J2: =IF(I2<Phu_tai!$D$15,Params!$D$27*I2,IF(I2<Phu_tai!$D$15+Phu_tai!$D$17,Params!$D$26,IF(I2<Phu_tai!$D$18,Params!$D$26-Params!$D$27*(I2-Phu_tai!$D$15-Phu_tai!$D$17),0)))+IF(AND((I2-Phu_tai!$D$18-Phu_tai!$D$40)>=0,(I2-Phu_tai!$D$18-Phu_tai!$D$40)<Phu_tai!$D$18),-(IF((I2-Phu_tai!$D$18-Phu_tai!$D$40)<Phu_tai!$D$15,Params!$D$27*(I2-Phu_tai!$D$18-Phu_tai!$D$40),IF((I2-Phu_tai!$D$18-Phu_tai!$D$40)<Phu_tai!$D$15+Phu_tai!$D$17,Params!$D$26,Params!$D$26-Params!$D$27*((I2-Phu_tai!$D$18-Phu_tai!$D$40)-Phu_tai!$D$15-Phu_tai!$D$17)))),0) | K2: 0 | L2: =IF(AND(K2<0.0001,J2=0,I2>0),0,Phu_tai!$D$12+Phu_tai!$D$24*J2/Params!$D$26) | M2: =IF(AND(K2<0.0001,J2=0,I2>0),0,Phu_tai!$D$13+Phu_tai!$D$25*J2/Params!$D$26)
A3: wbx | B3: Tốc độ góc trục bánh xe | C3: ω_bx | D3: =2*Params!$D$12/Params!$D$15 | E3: rad/s | F3: 2v/D | I3: =1*Phu_tai!$D$39 | J3: =IF(I3<Phu_tai!$D$15,Params!$D$27*I3,IF(I3<Phu_tai!$D$15+Phu_tai!$D$17,Params!$D$26,IF(I3<Phu_tai!$D$18,Params!$D$26-Params!$D$27*(I3-Phu_tai!$D$15-Phu_tai!$D$17),0)))+IF(AND((I3-Phu_tai!$D$18-Phu_tai!$D$40)>=0,(I3-Phu_tai!$D$18-Phu_tai!$D$40)<Phu_tai!$D$18),-(IF((I3-Phu_tai!$D$18-Phu_tai!$D$40)<Phu_tai!$D$15,Params!$D$27*(I3-Phu_tai!$D$18-Phu_tai!$D$40),IF((I3-Phu_tai!$D$18-Phu_tai!$D$40)<Phu_tai!$D$15+Phu_tai!$D$17,Params!$D$26,Params!$D$26-Params!$D$27*((I3-Phu_tai!$D$18-Phu_tai!$D$40)-Phu_tai!$D$15-Phu_tai!$D$17)))),0) | K3: =MAX(0,K2+(J3+J2)/2*Phu_tai!$D$39) | L3: =IF(AND(K3<0.0001,J3=0,I3>0),0,Phu_tai!$D$12+Phu_tai!$D$24*J3/Params!$D$26) | M3: =IF(AND(K3<0.0001,J3=0,I3>0),0,Phu_tai!$D$13+Phu_tai!$D$25*J3/Params!$D$26)
A4: Fc | B4: Lực cản tĩnh đầy tải | C4: F_c | D4: =Params!$D$24 | E4: N | F4: =P-20 | I4: =2*Phu_tai!$D$39 | J4: =IF(I4<Phu_tai!$D$15,Params!$D$27*I4,IF(I4<Phu_tai!$D$15+Phu_tai!$D$17,Params!$D$26,IF(I4<Phu_tai!$D$18,Params!$D$26-Params!$D$27*(I4-Phu_tai!$D$15-Phu_tai!$D$17),0)))+IF(AND((I4-Phu_tai!$D$18-Phu_tai!$D$40)>=0,(I4-Phu_tai!$D$18-Phu_tai!$D$40)<Phu_tai!$D$18),-(IF((I4-Phu_tai!$D$18-Phu_tai!$D$40)<Phu_tai!$D$15,Params!$D$27*(I4-Phu_tai!$D$18-Phu_tai!$D$40),IF((I4-Phu_tai!$D$18-Phu_tai!$D$40)<Phu_tai!$D$15+Phu_tai!$D$17,Params!$D$26,Params!$D$26-Params!$D$27*((I4-Phu_tai!$D$18-Phu_tai!$D$40)-Phu_tai!$D$15-Phu_tai!$D$17)))),0) | K4: =MAX(0,K3+(J4+J3)/2*Phu_tai!$D$39) | L4: =IF(AND(K4<0.0001,J4=0,I4>0),0,Phu_tai!$D$12+Phu_tai!$D$24*J4/Params!$D$26) | M4: =IF(AND(K4<0.0001,J4=0,I4>0),0,Phu_tai!$D$13+Phu_tai!$D$25*J4/Params!$D$26)
A5: Fc0 | B5: Lực cản tĩnh không tải | C5: F_c,0 | D5: =Params!$D$7*Params!$D$9*Params!$D$16 | E5: N | F5: m_0·g·w_0 | I5: =3*Phu_tai!$D$39 | J5: =IF(I5<Phu_tai!$D$15,Params!$D$27*I5,IF(I5<Phu_tai!$D$15+Phu_tai!$D$17,Params!$D$26,IF(I5<Phu_tai!$D$18,Params!$D$26-Params!$D$27*(I5-Phu_tai!$D$15-Phu_tai!$D$17),0)))+IF(AND((I5-Phu_tai!$D$18-Phu_tai!$D$40)>=0,(I5-Phu_tai!$D$18-Phu_tai!$D$40)<Phu_tai!$D$18),-(IF((I5-Phu_tai!$D$18-Phu_tai!$D$40)<Phu_tai!$D$15,Params!$D$27*(I5-Phu_tai!$D$18-Phu_tai!$D$40),IF((I5-Phu_tai!$D$18-Phu_tai!$D$40)<Phu_tai!$D$15+Phu_tai!$D$17,Params!$D$26,Params!$D$26-Params!$D$27*((I5-Phu_tai!$D$18-Phu_tai!$D$40)-Phu_tai!$D$15-Phu_tai!$D$17)))),0) | K5: =MAX(0,K4+(J5+J4)/2*Phu_tai!$D$39) | L5: =IF(AND(K5<0.0001,J5=0,I5>0),0,Phu_tai!$D$12+Phu_tai!$D$24*J5/Params!$D$26) | M5: =IF(AND(K5<0.0001,J5=0,I5>0),0,Phu_tai!$D$13+Phu_tai!$D$25*J5/Params!$D$26)
A6: Pt | B6: Công suất cản tĩnh | C6: P_tĩnh | D6: =Phu_tai!$D$4*Params!$D$12/Params!$D$18 | E6: W | F6: F_c·v/η | I6: =4*Phu_tai!$D$39 | J6: =IF(I6<Phu_tai!$D$15,Params!$D$27*I6,IF(I6<Phu_tai!$D$15+Phu_tai!$D$17,Params!$D$26,IF(I6<Phu_tai!$D$18,Params!$D$26-Params!$D$27*(I6-Phu_tai!$D$15-Phu_tai!$D$17),0)))+IF(AND((I6-Phu_tai!$D$18-Phu_tai!$D$40)>=0,(I6-Phu_tai!$D$18-Phu_tai!$D$40)<Phu_tai!$D$18),-(IF((I6-Phu_tai!$D$18-Phu_tai!$D$40)<Phu_tai!$D$15,Params!$D$27*(I6-Phu_tai!$D$18-Phu_tai!$D$40),IF((I6-Phu_tai!$D$18-Phu_tai!$D$40)<Phu_tai!$D$15+Phu_tai!$D$17,Params!$D$26,Params!$D$26-Params!$D$27*((I6-Phu_tai!$D$18-Phu_tai!$D$40)-Phu_tai!$D$15-Phu_tai!$D$17)))),0) | K6: =MAX(0,K5+(J6+J5)/2*Phu_tai!$D$39) | L6: =IF(AND(K6<0.0001,J6=0,I6>0),0,Phu_tai!$D$12+Phu_tai!$D$24*J6/Params!$D$26) | M6: =IF(AND(K6<0.0001,J6=0,I6>0),0,Phu_tai!$D$13+Phu_tai!$D$25*J6/Params!$D$26)
A7: Fbam | B7: Lực bám bánh dẫn đầy tải | C7: F_bám | D7: =Params!$D$17*Params!$D$29*Params!$D$6*Params!$D$9 | E7: N | F7: φ·k_dẫn·M_Σ·g | I7: =5*Phu_tai!$D$39 | J7: =IF(I7<Phu_tai!$D$15,Params!$D$27*I7,IF(I7<Phu_tai!$D$15+Phu_tai!$D$17,Params!$D$26,IF(I7<Phu_tai!$D$18,Params!$D$26-Params!$D$27*(I7-Phu_tai!$D$15-Phu_tai!$D$17),0)))+IF(AND((I7-Phu_tai!$D$18-Phu_tai!$D$40)>=0,(I7-Phu_tai!$D$18-Phu_tai!$D$40)<Phu_tai!$D$18),-(IF((I7-Phu_tai!$D$18-Phu_tai!$D$40)<Phu_tai!$D$15,Params!$D$27*(I7-Phu_tai!$D$18-Phu_tai!$D$40),IF((I7-Phu_tai!$D$18-Phu_tai!$D$40)<Phu_tai!$D$15+Phu_tai!$D$17,Params!$D$26,Params!$D$26-Params!$D$27*((I7-Phu_tai!$D$18-Phu_tai!$D$40)-Phu_tai!$D$15-Phu_tai!$D$17)))),0) | K7: =MAX(0,K6+(J7+J6)/2*Phu_tai!$D$39) | L7: =IF(AND(K7<0.0001,J7=0,I7>0),0,Phu_tai!$D$12+Phu_tai!$D$24*J7/Params!$D$26) | M7: =IF(AND(K7<0.0001,J7=0,I7>0),0,Phu_tai!$D$13+Phu_tai!$D$25*J7/Params!$D$26)
A8: B. Quy đổi về trục động cơ — Bài 3 [R5] | I8: =6*Phu_tai!$D$39 | J8: =IF(I8<Phu_tai!$D$15,Params!$D$27*I8,IF(I8<Phu_tai!$D$15+Phu_tai!$D$17,Params!$D$26,IF(I8<Phu_tai!$D$18,Params!$D$26-Params!$D$27*(I8-Phu_tai!$D$15-Phu_tai!$D$17),0)))+IF(AND((I8-Phu_tai!$D$18-Phu_tai!$D$40)>=0,(I8-Phu_tai!$D$18-Phu_tai!$D$40)<Phu_tai!$D$18),-(IF((I8-Phu_tai!$D$18-Phu_tai!$D$40)<Phu_tai!$D$15,Params!$D$27*(I8-Phu_tai!$D$18-Phu_tai!$D$40),IF((I8-Phu_tai!$D$18-Phu_tai!$D$40)<Phu_tai!$D$15+Phu_tai!$D$17,Params!$D$26,Params!$D$26-Params!$D$27*((I8-Phu_tai!$D$18-Phu_tai!$D$40)-Phu_tai!$D$15-Phu_tai!$D$17)))),0) | K8: =MAX(0,K7+(J8+J7)/2*Phu_tai!$D$39) | L8: =IF(AND(K8<0.0001,J8=0,I8>0),0,Phu_tai!$D$12+Phu_tai!$D$24*J8/Params!$D$26) | M8: =IF(AND(K8<0.0001,J8=0,I8>0),0,Phu_tai!$D$13+Phu_tai!$D$25*J8/Params!$D$26)
A9: k | B9: Hệ số quy đổi tịnh tiến–quay | C9: k_qđ | D9: =Params!$D$15/(2*Params!$D$42) | E9: m/rad | F9: D/(2i) | I9: =7*Phu_tai!$D$39 | J9: =IF(I9<Phu_tai!$D$15,Params!$D$27*I9,IF(I9<Phu_tai!$D$15+Phu_tai!$D$17,Params!$D$26,IF(I9<Phu_tai!$D$18,Params!$D$26-Params!$D$27*(I9-Phu_tai!$D$15-Phu_tai!$D$17),0)))+IF(AND((I9-Phu_tai!$D$18-Phu_tai!$D$40)>=0,(I9-Phu_tai!$D$18-Phu_tai!$D$40)<Phu_tai!$D$18),-(IF((I9-Phu_tai!$D$18-Phu_tai!$D$40)<Phu_tai!$D$15,Params!$D$27*(I9-Phu_tai!$D$18-Phu_tai!$D$40),IF((I9-Phu_tai!$D$18-Phu_tai!$D$40)<Phu_tai!$D$15+Phu_tai!$D$17,Params!$D$26,Params!$D$26-Params!$D$27*((I9-Phu_tai!$D$18-Phu_tai!$D$40)-Phu_tai!$D$15-Phu_tai!$D$17)))),0) | K9: =MAX(0,K8+(J9+J8)/2*Phu_tai!$D$39) | L9: =IF(AND(K9<0.0001,J9=0,I9>0),0,Phu_tai!$D$12+Phu_tai!$D$24*J9/Params!$D$26) | M9: =IF(AND(K9<0.0001,J9=0,I9>0),0,Phu_tai!$D$13+Phu_tai!$D$25*J9/Params!$D$26)
A10: wm | B10: Tốc độ động cơ khi xe chạy v_max | C10: ω_m | D10: =Params!$D$12/Phu_tai!$D$9 | E10: rad/s | F10: v/k | I10: =8*Phu_tai!$D$39 | J10: =IF(I10<Phu_tai!$D$15,Params!$D$27*I10,IF(I10<Phu_tai!$D$15+Phu_tai!$D$17,Params!$D$26,IF(I10<Phu_tai!$D$18,Params!$D$26-Params!$D$27*(I10-Phu_tai!$D$15-Phu_tai!$D$17),0)))+IF(AND((I10-Phu_tai!$D$18-Phu_tai!$D$40)>=0,(I10-Phu_tai!$D$18-Phu_tai!$D$40)<Phu_tai!$D$18),-(IF((I10-Phu_tai!$D$18-Phu_tai!$D$40)<Phu_tai!$D$15,Params!$D$27*(I10-Phu_tai!$D$18-Phu_tai!$D$40),IF((I10-Phu_tai!$D$18-Phu_tai!$D$40)<Phu_tai!$D$15+Phu_tai!$D$17,Params!$D$26,Params!$D$26-Params!$D$27*((I10-Phu_tai!$D$18-Phu_tai!$D$40)-Phu_tai!$D$15-Phu_tai!$D$17)))),0) | K10: =MAX(0,K9+(J10+J9)/2*Phu_tai!$D$39) | L10: =IF(AND(K10<0.0001,J10=0,I10>0),0,Phu_tai!$D$12+Phu_tai!$D$24*J10/Params!$D$26) | M10: =IF(AND(K10<0.0001,J10=0,I10>0),0,Phu_tai!$D$13+Phu_tai!$D$25*J10/Params!$D$26)
A11: nm | B11: Tốc độ động cơ khi xe chạy v_max | C11: n_m | D11: =Phu_tai!$D$10*60/(2*PI()) | E11: vg/ph | I11: =9*Phu_tai!$D$39 | J11: =IF(I11<Phu_tai!$D$15,Params!$D$27*I11,IF(I11<Phu_tai!$D$15+Phu_tai!$D$17,Params!$D$26,IF(I11<Phu_tai!$D$18,Params!$D$26-Params!$D$27*(I11-Phu_tai!$D$15-Phu_tai!$D$17),0)))+IF(AND((I11-Phu_tai!$D$18-Phu_tai!$D$40)>=0,(I11-Phu_tai!$D$18-Phu_tai!$D$40)<Phu_tai!$D$18),-(IF((I11-Phu_tai!$D$18-Phu_tai!$D$40)<Phu_tai!$D$15,Params!$D$27*(I11-Phu_tai!$D$18-Phu_tai!$D$40),IF((I11-Phu_tai!$D$18-Phu_tai!$D$40)<Phu_tai!$D$15+Phu_tai!$D$17,Params!$D$26,Params!$D$26-Params!$D$27*((I11-Phu_tai!$D$18-Phu_tai!$D$40)-Phu_tai!$D$15-Phu_tai!$D$17)))),0) | K11: =MAX(0,K10+(J11+J10)/2*Phu_tai!$D$39) | L11: =IF(AND(K11<0.0001,J11=0,I11>0),0,Phu_tai!$D$12+Phu_tai!$D$24*J11/Params!$D$26) | M11: =IF(AND(K11<0.0001,J11=0,I11>0),0,Phu_tai!$D$13+Phu_tai!$D$25*J11/Params!$D$26)
A12: Mc | B12: Mô-men cản đầy tải quy về trục ĐC | C12: M_c | D12: =Phu_tai!$D$4*Phu_tai!$D$9/Params!$D$18 | E12: N·m | F12: F_c·k/η | I12: =10*Phu_tai!$D$39 | J12: =IF(I12<Phu_tai!$D$15,Params!$D$27*I12,IF(I12<Phu_tai!$D$15+Phu_tai!$D$17,Params!$D$26,IF(I12<Phu_tai!$D$18,Params!$D$26-Params!$D$27*(I12-Phu_tai!$D$15-Phu_tai!$D$17),0)))+IF(AND((I12-Phu_tai!$D$18-Phu_tai!$D$40)>=0,(I12-Phu_tai!$D$18-Phu_tai!$D$40)<Phu_tai!$D$18),-(IF((I12-Phu_tai!$D$18-Phu_tai!$D$40)<Phu_tai!$D$15,Params!$D$27*(I12-Phu_tai!$D$18-Phu_tai!$D$40),IF((I12-Phu_tai!$D$18-Phu_tai!$D$40)<Phu_tai!$D$15+Phu_tai!$D$17,Params!$D$26,Params!$D$26-Params!$D$27*((I12-Phu_tai!$D$18-Phu_tai!$D$40)-Phu_tai!$D$15-Phu_tai!$D$17)))),0) | K12: =MAX(0,K11+(J12+J11)/2*Phu_tai!$D$39) | L12: =IF(AND(K12<0.0001,J12=0,I12>0),0,Phu_tai!$D$12+Phu_tai!$D$24*J12/Params!$D$26) | M12: =IF(AND(K12<0.0001,J12=0,I12>0),0,Phu_tai!$D$13+Phu_tai!$D$25*J12/Params!$D$26)
A13: Mc0 | B13: Mô-men cản không tải | C13: M_c,0 | D13: =Phu_tai!$D$5*Phu_tai!$D$9/Params!$D$18 | E13: N·m | I13: =11*Phu_tai!$D$39 | J13: =IF(I13<Phu_tai!$D$15,Params!$D$27*I13,IF(I13<Phu_tai!$D$15+Phu_tai!$D$17,Params!$D$26,IF(I13<Phu_tai!$D$18,Params!$D$26-Params!$D$27*(I13-Phu_tai!$D$15-Phu_tai!$D$17),0)))+IF(AND((I13-Phu_tai!$D$18-Phu_tai!$D$40)>=0,(I13-Phu_tai!$D$18-Phu_tai!$D$40)<Phu_tai!$D$18),-(IF((I13-Phu_tai!$D$18-Phu_tai!$D$40)<Phu_tai!$D$15,Params!$D$27*(I13-Phu_tai!$D$18-Phu_tai!$D$40),IF((I13-Phu_tai!$D$18-Phu_tai!$D$40)<Phu_tai!$D$15+Phu_tai!$D$17,Params!$D$26,Params!$D$26-Params!$D$27*((I13-Phu_tai!$D$18-Phu_tai!$D$40)-Phu_tai!$D$15-Phu_tai!$D$17)))),0) | K13: =MAX(0,K12+(J13+J12)/2*Phu_tai!$D$39) | L13: =IF(AND(K13<0.0001,J13=0,I13>0),0,Phu_tai!$D$12+Phu_tai!$D$24*J13/Params!$D$26) | M13: =IF(AND(K13<0.0001,J13=0,I13>0),0,Phu_tai!$D$13+Phu_tai!$D$25*J13/Params!$D$26)
A14: C. Quỹ đạo S-curve 7 đoạn với lượng đặt a*, ρ* — [R9-11] | I14: =12*Phu_tai!$D$39 | J14: =IF(I14<Phu_tai!$D$15,Params!$D$27*I14,IF(I14<Phu_tai!$D$15+Phu_tai!$D$17,Params!$D$26,IF(I14<Phu_tai!$D$18,Params!$D$26-Params!$D$27*(I14-Phu_tai!$D$15-Phu_tai!$D$17),0)))+IF(AND((I14-Phu_tai!$D$18-Phu_tai!$D$40)>=0,(I14-Phu_tai!$D$18-Phu_tai!$D$40)<Phu_tai!$D$18),-(IF((I14-Phu_tai!$D$18-Phu_tai!$D$40)<Phu_tai!$D$15,Params!$D$27*(I14-Phu_tai!$D$18-Phu_tai!$D$40),IF((I14-Phu_tai!$D$18-Phu_tai!$D$40)<Phu_tai!$D$15+Phu_tai!$D$17,Params!$D$26,Params!$D$26-Params!$D$27*((I14-Phu_tai!$D$18-Phu_tai!$D$40)-Phu_tai!$D$15-Phu_tai!$D$17)))),0) | K14: =MAX(0,K13+(J14+J13)/2*Phu_tai!$D$39) | L14: =IF(AND(K14<0.0001,J14=0,I14>0),0,Phu_tai!$D$12+Phu_tai!$D$24*J14/Params!$D$26) | M14: =IF(AND(K14<0.0001,J14=0,I14>0),0,Phu_tai!$D$13+Phu_tai!$D$25*J14/Params!$D$26)
A15: Tj | B15: Thời gian tăng/giảm độ giật | C15: T_j | D15: =Params!$D$26/Params!$D$27 | E15: s | F15: a*/ρ* | I15: =13*Phu_tai!$D$39 | J15: =IF(I15<Phu_tai!$D$15,Params!$D$27*I15,IF(I15<Phu_tai!$D$15+Phu_tai!$D$17,Params!$D$26,IF(I15<Phu_tai!$D$18,Params!$D$26-Params!$D$27*(I15-Phu_tai!$D$15-Phu_tai!$D$17),0)))+IF(AND((I15-Phu_tai!$D$18-Phu_tai!$D$40)>=0,(I15-Phu_tai!$D$18-Phu_tai!$D$40)<Phu_tai!$D$18),-(IF((I15-Phu_tai!$D$18-Phu_tai!$D$40)<Phu_tai!$D$15,Params!$D$27*(I15-Phu_tai!$D$18-Phu_tai!$D$40),IF((I15-Phu_tai!$D$18-Phu_tai!$D$40)<Phu_tai!$D$15+Phu_tai!$D$17,Params!$D$26,Params!$D$26-Params!$D$27*((I15-Phu_tai!$D$18-Phu_tai!$D$40)-Phu_tai!$D$15-Phu_tai!$D$17)))),0) | K15: =MAX(0,K14+(J15+J14)/2*Phu_tai!$D$39) | L15: =IF(AND(K15<0.0001,J15=0,I15>0),0,Phu_tai!$D$12+Phu_tai!$D$24*J15/Params!$D$26) | M15: =IF(AND(K15<0.0001,J15=0,I15>0),0,Phu_tai!$D$13+Phu_tai!$D$25*J15/Params!$D$26)
A16: vlim | B16: Vận tốc ngưỡng để có đoạn gia tốc không đổi | C16: a*²/ρ* | D16: =Params!$D$26^2/Params!$D$27 | E16: m/s | F16: Phải < v_max | I16: =14*Phu_tai!$D$39 | J16: =IF(I16<Phu_tai!$D$15,Params!$D$27*I16,IF(I16<Phu_tai!$D$15+Phu_tai!$D$17,Params!$D$26,IF(I16<Phu_tai!$D$18,Params!$D$26-Params!$D$27*(I16-Phu_tai!$D$15-Phu_tai!$D$17),0)))+IF(AND((I16-Phu_tai!$D$18-Phu_tai!$D$40)>=0,(I16-Phu_tai!$D$18-Phu_tai!$D$40)<Phu_tai!$D$18),-(IF((I16-Phu_tai!$D$18-Phu_tai!$D$40)<Phu_tai!$D$15,Params!$D$27*(I16-Phu_tai!$D$18-Phu_tai!$D$40),IF((I16-Phu_tai!$D$18-Phu_tai!$D$40)<Phu_tai!$D$15+Phu_tai!$D$17,Params!$D$26,Params!$D$26-Params!$D$27*((I16-Phu_tai!$D$18-Phu_tai!$D$40)-Phu_tai!$D$15-Phu_tai!$D$17)))),0) | K16: =MAX(0,K15+(J16+J15)/2*Phu_tai!$D$39) | L16: =IF(AND(K16<0.0001,J16=0,I16>0),0,Phu_tai!$D$12+Phu_tai!$D$24*J16/Params!$D$26) | M16: =IF(AND(K16<0.0001,J16=0,I16>0),0,Phu_tai!$D$13+Phu_tai!$D$25*J16/Params!$D$26)
A17: Ta | B17: Thời gian gia tốc không đổi | C17: T_a | D17: =Params!$D$12/Params!$D$26-Phu_tai!$D$15 | E17: s | F17: v/a* − T_j | I17: =15*Phu_tai!$D$39 | J17: =IF(I17<Phu_tai!$D$15,Params!$D$27*I17,IF(I17<Phu_tai!$D$15+Phu_tai!$D$17,Params!$D$26,IF(I17<Phu_tai!$D$18,Params!$D$26-Params!$D$27*(I17-Phu_tai!$D$15-Phu_tai!$D$17),0)))+IF(AND((I17-Phu_tai!$D$18-Phu_tai!$D$40)>=0,(I17-Phu_tai!$D$18-Phu_tai!$D$40)<Phu_tai!$D$18),-(IF((I17-Phu_tai!$D$18-Phu_tai!$D$40)<Phu_tai!$D$15,Params!$D$27*(I17-Phu_tai!$D$18-Phu_tai!$D$40),IF((I17-Phu_tai!$D$18-Phu_tai!$D$40)<Phu_tai!$D$15+Phu_tai!$D$17,Params!$D$26,Params!$D$26-Params!$D$27*((I17-Phu_tai!$D$18-Phu_tai!$D$40)-Phu_tai!$D$15-Phu_tai!$D$17)))),0) | K17: =MAX(0,K16+(J17+J16)/2*Phu_tai!$D$39) | L17: =IF(AND(K17<0.0001,J17=0,I17>0),0,Phu_tai!$D$12+Phu_tai!$D$24*J17/Params!$D$26) | M17: =IF(AND(K17<0.0001,J17=0,I17>0),0,Phu_tai!$D$13+Phu_tai!$D$25*J17/Params!$D$26)
A18: tacc | B18: Thời gian tăng tốc | C18: t_acc | D18: =2*Phu_tai!$D$15+Phu_tai!$D$17 | E18: s | F18: 2T_j + T_a | I18: =16*Phu_tai!$D$39 | J18: =IF(I18<Phu_tai!$D$15,Params!$D$27*I18,IF(I18<Phu_tai!$D$15+Phu_tai!$D$17,Params!$D$26,IF(I18<Phu_tai!$D$18,Params!$D$26-Params!$D$27*(I18-Phu_tai!$D$15-Phu_tai!$D$17),0)))+IF(AND((I18-Phu_tai!$D$18-Phu_tai!$D$40)>=0,(I18-Phu_tai!$D$18-Phu_tai!$D$40)<Phu_tai!$D$18),-(IF((I18-Phu_tai!$D$18-Phu_tai!$D$40)<Phu_tai!$D$15,Params!$D$27*(I18-Phu_tai!$D$18-Phu_tai!$D$40),IF((I18-Phu_tai!$D$18-Phu_tai!$D$40)<Phu_tai!$D$15+Phu_tai!$D$17,Params!$D$26,Params!$D$26-Params!$D$27*((I18-Phu_tai!$D$18-Phu_tai!$D$40)-Phu_tai!$D$15-Phu_tai!$D$17)))),0) | K18: =MAX(0,K17+(J18+J17)/2*Phu_tai!$D$39) | L18: =IF(AND(K18<0.0001,J18=0,I18>0),0,Phu_tai!$D$12+Phu_tai!$D$24*J18/Params!$D$26) | M18: =IF(AND(K18<0.0001,J18=0,I18>0),0,Phu_tai!$D$13+Phu_tai!$D$25*J18/Params!$D$26)
A19: sacc | B19: Quãng đường tăng tốc | C19: s_acc | D19: =Params!$D$12*Phu_tai!$D$18/2 | E19: m | I19: =17*Phu_tai!$D$39 | J19: =IF(I19<Phu_tai!$D$15,Params!$D$27*I19,IF(I19<Phu_tai!$D$15+Phu_tai!$D$17,Params!$D$26,IF(I19<Phu_tai!$D$18,Params!$D$26-Params!$D$27*(I19-Phu_tai!$D$15-Phu_tai!$D$17),0)))+IF(AND((I19-Phu_tai!$D$18-Phu_tai!$D$40)>=0,(I19-Phu_tai!$D$18-Phu_tai!$D$40)<Phu_tai!$D$18),-(IF((I19-Phu_tai!$D$18-Phu_tai!$D$40)<Phu_tai!$D$15,Params!$D$27*(I19-Phu_tai!$D$18-Phu_tai!$D$40),IF((I19-Phu_tai!$D$18-Phu_tai!$D$40)<Phu_tai!$D$15+Phu_tai!$D$17,Params!$D$26,Params!$D$26-Params!$D$27*((I19-Phu_tai!$D$18-Phu_tai!$D$40)-Phu_tai!$D$15-Phu_tai!$D$17)))),0) | K19: =MAX(0,K18+(J19+J18)/2*Phu_tai!$D$39) | L19: =IF(AND(K19<0.0001,J19=0,I19>0),0,Phu_tai!$D$12+Phu_tai!$D$24*J19/Params!$D$26) | M19: =IF(AND(K19<0.0001,J19=0,I19>0),0,Phu_tai!$D$13+Phu_tai!$D$25*J19/Params!$D$26)
A20: f2 | B20: Hệ số trung bình a²(t)/a*² pha tăng tốc | C20: f₂ | D20: =(2*Phu_tai!$D$15/3+Phu_tai!$D$17)/Phu_tai!$D$18 | E20: - | F20: Cho tính M_đt | I20: =18*Phu_tai!$D$39 | J20: =IF(I20<Phu_tai!$D$15,Params!$D$27*I20,IF(I20<Phu_tai!$D$15+Phu_tai!$D$17,Params!$D$26,IF(I20<Phu_tai!$D$18,Params!$D$26-Params!$D$27*(I20-Phu_tai!$D$15-Phu_tai!$D$17),0)))+IF(AND((I20-Phu_tai!$D$18-Phu_tai!$D$40)>=0,(I20-Phu_tai!$D$18-Phu_tai!$D$40)<Phu_tai!$D$18),-(IF((I20-Phu_tai!$D$18-Phu_tai!$D$40)<Phu_tai!$D$15,Params!$D$27*(I20-Phu_tai!$D$18-Phu_tai!$D$40),IF((I20-Phu_tai!$D$18-Phu_tai!$D$40)<Phu_tai!$D$15+Phu_tai!$D$17,Params!$D$26,Params!$D$26-Params!$D$27*((I20-Phu_tai!$D$18-Phu_tai!$D$40)-Phu_tai!$D$15-Phu_tai!$D$17)))),0) | K20: =MAX(0,K19+(J20+J19)/2*Phu_tai!$D$39) | L20: =IF(AND(K20<0.0001,J20=0,I20>0),0,Phu_tai!$D$12+Phu_tai!$D$24*J20/Params!$D$26) | M20: =IF(AND(K20<0.0001,J20=0,I20>0),0,Phu_tai!$D$13+Phu_tai!$D$25*J20/Params!$D$26)
A21: th0 | B21: Góc lệch cáp tựa tĩnh ứng a* | C21: θ_0 | D21: =DEGREES(ATAN(Params!$D$26/Params!$D$9)) | E21: ° | F21: atan(a*/g) | I21: =19*Phu_tai!$D$39 | J21: =IF(I21<Phu_tai!$D$15,Params!$D$27*I21,IF(I21<Phu_tai!$D$15+Phu_tai!$D$17,Params!$D$26,IF(I21<Phu_tai!$D$18,Params!$D$26-Params!$D$27*(I21-Phu_tai!$D$15-Phu_tai!$D$17),0)))+IF(AND((I21-Phu_tai!$D$18-Phu_tai!$D$40)>=0,(I21-Phu_tai!$D$18-Phu_tai!$D$40)<Phu_tai!$D$18),-(IF((I21-Phu_tai!$D$18-Phu_tai!$D$40)<Phu_tai!$D$15,Params!$D$27*(I21-Phu_tai!$D$18-Phu_tai!$D$40),IF((I21-Phu_tai!$D$18-Phu_tai!$D$40)<Phu_tai!$D$15+Phu_tai!$D$17,Params!$D$26,Params!$D$26-Params!$D$27*((I21-Phu_tai!$D$18-Phu_tai!$D$40)-Phu_tai!$D$15-Phu_tai!$D$17)))),0) | K21: =MAX(0,K20+(J21+J20)/2*Phu_tai!$D$39) | L21: =IF(AND(K21<0.0001,J21=0,I21>0),0,Phu_tai!$D$12+Phu_tai!$D$24*J21/Params!$D$26) | M21: =IF(AND(K21<0.0001,J21=0,I21>0),0,Phu_tai!$D$13+Phu_tai!$D$25*J21/Params!$D$26)
A22: D. Mô-men động và mô-men từng pha (động cơ đang chọn) | I22: =20*Phu_tai!$D$39 | J22: =IF(I22<Phu_tai!$D$15,Params!$D$27*I22,IF(I22<Phu_tai!$D$15+Phu_tai!$D$17,Params!$D$26,IF(I22<Phu_tai!$D$18,Params!$D$26-Params!$D$27*(I22-Phu_tai!$D$15-Phu_tai!$D$17),0)))+IF(AND((I22-Phu_tai!$D$18-Phu_tai!$D$40)>=0,(I22-Phu_tai!$D$18-Phu_tai!$D$40)<Phu_tai!$D$18),-(IF((I22-Phu_tai!$D$18-Phu_tai!$D$40)<Phu_tai!$D$15,Params!$D$27*(I22-Phu_tai!$D$18-Phu_tai!$D$40),IF((I22-Phu_tai!$D$18-Phu_tai!$D$40)<Phu_tai!$D$15+Phu_tai!$D$17,Params!$D$26,Params!$D$26-Params!$D$27*((I22-Phu_tai!$D$18-Phu_tai!$D$40)-Phu_tai!$D$15-Phu_tai!$D$17)))),0) | K22: =MAX(0,K21+(J22+J21)/2*Phu_tai!$D$39) | L22: =IF(AND(K22<0.0001,J22=0,I22>0),0,Phu_tai!$D$12+Phu_tai!$D$24*J22/Params!$D$26) | M22: =IF(AND(K22<0.0001,J22=0,I22>0),0,Phu_tai!$D$13+Phu_tai!$D$25*J22/Params!$D$26)
A23: Jl | B23: Quán tính tải quy đổi đầy tải | C23: J_tải | D23: =Params!$D$28*Params!$D$6*Phu_tai!$D$9^2 | E23: kg·m² | F23: δ·M_Σ·k² | I23: =21*Phu_tai!$D$39 | J23: =IF(I23<Phu_tai!$D$15,Params!$D$27*I23,IF(I23<Phu_tai!$D$15+Phu_tai!$D$17,Params!$D$26,IF(I23<Phu_tai!$D$18,Params!$D$26-Params!$D$27*(I23-Phu_tai!$D$15-Phu_tai!$D$17),0)))+IF(AND((I23-Phu_tai!$D$18-Phu_tai!$D$40)>=0,(I23-Phu_tai!$D$18-Phu_tai!$D$40)<Phu_tai!$D$18),-(IF((I23-Phu_tai!$D$18-Phu_tai!$D$40)<Phu_tai!$D$15,Params!$D$27*(I23-Phu_tai!$D$18-Phu_tai!$D$40),IF((I23-Phu_tai!$D$18-Phu_tai!$D$40)<Phu_tai!$D$15+Phu_tai!$D$17,Params!$D$26,Params!$D$26-Params!$D$27*((I23-Phu_tai!$D$18-Phu_tai!$D$40)-Phu_tai!$D$15-Phu_tai!$D$17)))),0) | K23: =MAX(0,K22+(J23+J22)/2*Phu_tai!$D$39) | L23: =IF(AND(K23<0.0001,J23=0,I23>0),0,Phu_tai!$D$12+Phu_tai!$D$24*J23/Params!$D$26) | M23: =IF(AND(K23<0.0001,J23=0,I23>0),0,Phu_tai!$D$13+Phu_tai!$D$25*J23/Params!$D$26)
A24: Mdg | B24: Mô-men động đầy tải tại a* | C24: M_đg | D24: =Params!$D$28*Params!$D$6*Params!$D$26*Phu_tai!$D$9/Params!$D$18+Catalogue!$H$15*Params!$D$26/Phu_tai!$D$9 | E24: N·m | F24: δM_Σa*k/η + J_B·a*/k | I24: =22*Phu_tai!$D$39 | J24: =IF(I24<Phu_tai!$D$15,Params!$D$27*I24,IF(I24<Phu_tai!$D$15+Phu_tai!$D$17,Params!$D$26,IF(I24<Phu_tai!$D$18,Params!$D$26-Params!$D$27*(I24-Phu_tai!$D$15-Phu_tai!$D$17),0)))+IF(AND((I24-Phu_tai!$D$18-Phu_tai!$D$40)>=0,(I24-Phu_tai!$D$18-Phu_tai!$D$40)<Phu_tai!$D$18),-(IF((I24-Phu_tai!$D$18-Phu_tai!$D$40)<Phu_tai!$D$15,Params!$D$27*(I24-Phu_tai!$D$18-Phu_tai!$D$40),IF((I24-Phu_tai!$D$18-Phu_tai!$D$40)<Phu_tai!$D$15+Phu_tai!$D$17,Params!$D$26,Params!$D$26-Params!$D$27*((I24-Phu_tai!$D$18-Phu_tai!$D$40)-Phu_tai!$D$15-Phu_tai!$D$17)))),0) | K24: =MAX(0,K23+(J24+J23)/2*Phu_tai!$D$39) | L24: =IF(AND(K24<0.0001,J24=0,I24>0),0,Phu_tai!$D$12+Phu_tai!$D$24*J24/Params!$D$26) | M24: =IF(AND(K24<0.0001,J24=0,I24>0),0,Phu_tai!$D$13+Phu_tai!$D$25*J24/Params!$D$26)
A25: Mdg0 | B25: Mô-men động không tải tại a* | C25: M_đg,0 | D25: =Params!$D$28*Params!$D$7*Params!$D$26*Phu_tai!$D$9/Params!$D$18+Catalogue!$H$15*Params!$D$26/Phu_tai!$D$9 | E25: N·m | I25: =23*Phu_tai!$D$39 | J25: =IF(I25<Phu_tai!$D$15,Params!$D$27*I25,IF(I25<Phu_tai!$D$15+Phu_tai!$D$17,Params!$D$26,IF(I25<Phu_tai!$D$18,Params!$D$26-Params!$D$27*(I25-Phu_tai!$D$15-Phu_tai!$D$17),0)))+IF(AND((I25-Phu_tai!$D$18-Phu_tai!$D$40)>=0,(I25-Phu_tai!$D$18-Phu_tai!$D$40)<Phu_tai!$D$18),-(IF((I25-Phu_tai!$D$18-Phu_tai!$D$40)<Phu_tai!$D$15,Params!$D$27*(I25-Phu_tai!$D$18-Phu_tai!$D$40),IF((I25-Phu_tai!$D$18-Phu_tai!$D$40)<Phu_tai!$D$15+Phu_tai!$D$17,Params!$D$26,Params!$D$26-Params!$D$27*((I25-Phu_tai!$D$18-Phu_tai!$D$40)-Phu_tai!$D$15-Phu_tai!$D$17)))),0) | K25: =MAX(0,K24+(J25+J24)/2*Phu_tai!$D$39) | L25: =IF(AND(K25<0.0001,J25=0,I25>0),0,Phu_tai!$D$12+Phu_tai!$D$24*J25/Params!$D$26) | M25: =IF(AND(K25<0.0001,J25=0,I25>0),0,Phu_tai!$D$13+Phu_tai!$D$25*J25/Params!$D$26)
A26: Mkd | B26: Mô-men đỉnh khi tăng tốc đầy tải | C26: M_max | D26: =Phu_tai!$D$12+Phu_tai!$D$24 | E26: N·m | F26: M_c + M_đg | I26: =24*Phu_tai!$D$39 | J26: =IF(I26<Phu_tai!$D$15,Params!$D$27*I26,IF(I26<Phu_tai!$D$15+Phu_tai!$D$17,Params!$D$26,IF(I26<Phu_tai!$D$18,Params!$D$26-Params!$D$27*(I26-Phu_tai!$D$15-Phu_tai!$D$17),0)))+IF(AND((I26-Phu_tai!$D$18-Phu_tai!$D$40)>=0,(I26-Phu_tai!$D$18-Phu_tai!$D$40)<Phu_tai!$D$18),-(IF((I26-Phu_tai!$D$18-Phu_tai!$D$40)<Phu_tai!$D$15,Params!$D$27*(I26-Phu_tai!$D$18-Phu_tai!$D$40),IF((I26-Phu_tai!$D$18-Phu_tai!$D$40)<Phu_tai!$D$15+Phu_tai!$D$17,Params!$D$26,Params!$D$26-Params!$D$27*((I26-Phu_tai!$D$18-Phu_tai!$D$40)-Phu_tai!$D$15-Phu_tai!$D$17)))),0) | K26: =MAX(0,K25+(J26+J25)/2*Phu_tai!$D$39) | L26: =IF(AND(K26<0.0001,J26=0,I26>0),0,Phu_tai!$D$12+Phu_tai!$D$24*J26/Params!$D$26) | M26: =IF(AND(K26<0.0001,J26=0,I26>0),0,Phu_tai!$D$13+Phu_tai!$D$25*J26/Params!$D$26)
A27: Mh | B27: Mô-men khi giảm tốc đầy tải (nhỏ nhất) | C27: M_h | D27: =Phu_tai!$D$12-Phu_tai!$D$24 | E27: N·m | F27: > 0: lực cản đủ hãm, không có năng lượng tái sinh | I27: =25*Phu_tai!$D$39 | J27: =IF(I27<Phu_tai!$D$15,Params!$D$27*I27,IF(I27<Phu_tai!$D$15+Phu_tai!$D$17,Params!$D$26,IF(I27<Phu_tai!$D$18,Params!$D$26-Params!$D$27*(I27-Phu_tai!$D$15-Phu_tai!$D$17),0)))+IF(AND((I27-Phu_tai!$D$18-Phu_tai!$D$40)>=0,(I27-Phu_tai!$D$18-Phu_tai!$D$40)<Phu_tai!$D$18),-(IF((I27-Phu_tai!$D$18-Phu_tai!$D$40)<Phu_tai!$D$15,Params!$D$27*(I27-Phu_tai!$D$18-Phu_tai!$D$40),IF((I27-Phu_tai!$D$18-Phu_tai!$D$40)<Phu_tai!$D$15+Phu_tai!$D$17,Params!$D$26,Params!$D$26-Params!$D$27*((I27-Phu_tai!$D$18-Phu_tai!$D$40)-Phu_tai!$D$15-Phu_tai!$D$17)))),0) | K27: =MAX(0,K26+(J27+J26)/2*Phu_tai!$D$39) | L27: =IF(AND(K27<0.0001,J27=0,I27>0),0,Phu_tai!$D$12+Phu_tai!$D$24*J27/Params!$D$26) | M27: =IF(AND(K27<0.0001,J27=0,I27>0),0,Phu_tai!$D$13+Phu_tai!$D$25*J27/Params!$D$26)
A28: Mkd0 | B28: Mô-men đỉnh khi tăng tốc không tải | C28: M_max,0 | D28: =Phu_tai!$D$13+Phu_tai!$D$25 | E28: N·m | I28: =26*Phu_tai!$D$39 | J28: =IF(I28<Phu_tai!$D$15,Params!$D$27*I28,IF(I28<Phu_tai!$D$15+Phu_tai!$D$17,Params!$D$26,IF(I28<Phu_tai!$D$18,Params!$D$26-Params!$D$27*(I28-Phu_tai!$D$15-Phu_tai!$D$17),0)))+IF(AND((I28-Phu_tai!$D$18-Phu_tai!$D$40)>=0,(I28-Phu_tai!$D$18-Phu_tai!$D$40)<Phu_tai!$D$18),-(IF((I28-Phu_tai!$D$18-Phu_tai!$D$40)<Phu_tai!$D$15,Params!$D$27*(I28-Phu_tai!$D$18-Phu_tai!$D$40),IF((I28-Phu_tai!$D$18-Phu_tai!$D$40)<Phu_tai!$D$15+Phu_tai!$D$17,Params!$D$26,Params!$D$26-Params!$D$27*((I28-Phu_tai!$D$18-Phu_tai!$D$40)-Phu_tai!$D$15-Phu_tai!$D$17)))),0) | K28: =MAX(0,K27+(J28+J27)/2*Phu_tai!$D$39) | L28: =IF(AND(K28<0.0001,J28=0,I28>0),0,Phu_tai!$D$12+Phu_tai!$D$24*J28/Params!$D$26) | M28: =IF(AND(K28<0.0001,J28=0,I28>0),0,Phu_tai!$D$13+Phu_tai!$D$25*J28/Params!$D$26)
A29: Mh0 | B29: Mô-men khi giảm tốc không tải | C29: M_h,0 | D29: =Phu_tai!$D$13-Phu_tai!$D$25 | E29: N·m | F29: < 0: hãm tái sinh nhỏ do quán tính rotor | I29: =27*Phu_tai!$D$39 | J29: =IF(I29<Phu_tai!$D$15,Params!$D$27*I29,IF(I29<Phu_tai!$D$15+Phu_tai!$D$17,Params!$D$26,IF(I29<Phu_tai!$D$18,Params!$D$26-Params!$D$27*(I29-Phu_tai!$D$15-Phu_tai!$D$17),0)))+IF(AND((I29-Phu_tai!$D$18-Phu_tai!$D$40)>=0,(I29-Phu_tai!$D$18-Phu_tai!$D$40)<Phu_tai!$D$18),-(IF((I29-Phu_tai!$D$18-Phu_tai!$D$40)<Phu_tai!$D$15,Params!$D$27*(I29-Phu_tai!$D$18-Phu_tai!$D$40),IF((I29-Phu_tai!$D$18-Phu_tai!$D$40)<Phu_tai!$D$15+Phu_tai!$D$17,Params!$D$26,Params!$D$26-Params!$D$27*((I29-Phu_tai!$D$18-Phu_tai!$D$40)-Phu_tai!$D$15-Phu_tai!$D$17)))),0) | K29: =MAX(0,K28+(J29+J28)/2*Phu_tai!$D$39) | L29: =IF(AND(K29<0.0001,J29=0,I29>0),0,Phu_tai!$D$12+Phu_tai!$D$24*J29/Params!$D$26) | M29: =IF(AND(K29<0.0001,J29=0,I29>0),0,Phu_tai!$D$13+Phu_tai!$D$25*J29/Params!$D$26)
A30: E. Chu trình S3-40% và mô-men đẳng trị — Bài 4 [R5] | I30: =28*Phu_tai!$D$39 | J30: =IF(I30<Phu_tai!$D$15,Params!$D$27*I30,IF(I30<Phu_tai!$D$15+Phu_tai!$D$17,Params!$D$26,IF(I30<Phu_tai!$D$18,Params!$D$26-Params!$D$27*(I30-Phu_tai!$D$15-Phu_tai!$D$17),0)))+IF(AND((I30-Phu_tai!$D$18-Phu_tai!$D$40)>=0,(I30-Phu_tai!$D$18-Phu_tai!$D$40)<Phu_tai!$D$18),-(IF((I30-Phu_tai!$D$18-Phu_tai!$D$40)<Phu_tai!$D$15,Params!$D$27*(I30-Phu_tai!$D$18-Phu_tai!$D$40),IF((I30-Phu_tai!$D$18-Phu_tai!$D$40)<Phu_tai!$D$15+Phu_tai!$D$17,Params!$D$26,Params!$D$26-Params!$D$27*((I30-Phu_tai!$D$18-Phu_tai!$D$40)-Phu_tai!$D$15-Phu_tai!$D$17)))),0) | K30: =MAX(0,K29+(J30+J29)/2*Phu_tai!$D$39) | L30: =IF(AND(K30<0.0001,J30=0,I30>0),0,Phu_tai!$D$12+Phu_tai!$D$24*J30/Params!$D$26) | M30: =IF(AND(K30<0.0001,J30=0,I30>0),0,Phu_tai!$D$13+Phu_tai!$D$25*J30/Params!$D$26)
A31: tlv | B31: Tổng thời gian đóng điện | C31: Σt_lv | D31: =Params!$D$19*Params!$D$20 | E31: s | F31: CD·T_ck | I31: =29*Phu_tai!$D$39 | J31: =IF(I31<Phu_tai!$D$15,Params!$D$27*I31,IF(I31<Phu_tai!$D$15+Phu_tai!$D$17,Params!$D$26,IF(I31<Phu_tai!$D$18,Params!$D$26-Params!$D$27*(I31-Phu_tai!$D$15-Phu_tai!$D$17),0)))+IF(AND((I31-Phu_tai!$D$18-Phu_tai!$D$40)>=0,(I31-Phu_tai!$D$18-Phu_tai!$D$40)<Phu_tai!$D$18),-(IF((I31-Phu_tai!$D$18-Phu_tai!$D$40)<Phu_tai!$D$15,Params!$D$27*(I31-Phu_tai!$D$18-Phu_tai!$D$40),IF((I31-Phu_tai!$D$18-Phu_tai!$D$40)<Phu_tai!$D$15+Phu_tai!$D$17,Params!$D$26,Params!$D$26-Params!$D$27*((I31-Phu_tai!$D$18-Phu_tai!$D$40)-Phu_tai!$D$15-Phu_tai!$D$17)))),0) | K31: =MAX(0,K30+(J31+J30)/2*Phu_tai!$D$39) | L31: =IF(AND(K31<0.0001,J31=0,I31>0),0,Phu_tai!$D$12+Phu_tai!$D$24*J31/Params!$D$26) | M31: =IF(AND(K31<0.0001,J31=0,I31>0),0,Phu_tai!$D$13+Phu_tai!$D$25*J31/Params!$D$26)
A32: tht | B32: Thời gian một hành trình | C32: t_ht | D32: =Phu_tai!$D$31/Params!$D$30 | E32: s | I32: =30*Phu_tai!$D$39 | J32: =IF(I32<Phu_tai!$D$15,Params!$D$27*I32,IF(I32<Phu_tai!$D$15+Phu_tai!$D$17,Params!$D$26,IF(I32<Phu_tai!$D$18,Params!$D$26-Params!$D$27*(I32-Phu_tai!$D$15-Phu_tai!$D$17),0)))+IF(AND((I32-Phu_tai!$D$18-Phu_tai!$D$40)>=0,(I32-Phu_tai!$D$18-Phu_tai!$D$40)<Phu_tai!$D$18),-(IF((I32-Phu_tai!$D$18-Phu_tai!$D$40)<Phu_tai!$D$15,Params!$D$27*(I32-Phu_tai!$D$18-Phu_tai!$D$40),IF((I32-Phu_tai!$D$18-Phu_tai!$D$40)<Phu_tai!$D$15+Phu_tai!$D$17,Params!$D$26,Params!$D$26-Params!$D$27*((I32-Phu_tai!$D$18-Phu_tai!$D$40)-Phu_tai!$D$15-Phu_tai!$D$17)))),0) | K32: =MAX(0,K31+(J32+J31)/2*Phu_tai!$D$39) | L32: =IF(AND(K32<0.0001,J32=0,I32>0),0,Phu_tai!$D$12+Phu_tai!$D$24*J32/Params!$D$26) | M32: =IF(AND(K32<0.0001,J32=0,I32>0),0,Phu_tai!$D$13+Phu_tai!$D$25*J32/Params!$D$26)
A33: tc | B33: Thời gian chạy đều mỗi hành trình | C33: t_đều | D33: =Phu_tai!$D$32-2*Phu_tai!$D$18 | E33: s | I33: =31*Phu_tai!$D$39 | J33: =IF(I33<Phu_tai!$D$15,Params!$D$27*I33,IF(I33<Phu_tai!$D$15+Phu_tai!$D$17,Params!$D$26,IF(I33<Phu_tai!$D$18,Params!$D$26-Params!$D$27*(I33-Phu_tai!$D$15-Phu_tai!$D$17),0)))+IF(AND((I33-Phu_tai!$D$18-Phu_tai!$D$40)>=0,(I33-Phu_tai!$D$18-Phu_tai!$D$40)<Phu_tai!$D$18),-(IF((I33-Phu_tai!$D$18-Phu_tai!$D$40)<Phu_tai!$D$15,Params!$D$27*(I33-Phu_tai!$D$18-Phu_tai!$D$40),IF((I33-Phu_tai!$D$18-Phu_tai!$D$40)<Phu_tai!$D$15+Phu_tai!$D$17,Params!$D$26,Params!$D$26-Params!$D$27*((I33-Phu_tai!$D$18-Phu_tai!$D$40)-Phu_tai!$D$15-Phu_tai!$D$17)))),0) | K33: =MAX(0,K32+(J33+J32)/2*Phu_tai!$D$39) | L33: =IF(AND(K33<0.0001,J33=0,I33>0),0,Phu_tai!$D$12+Phu_tai!$D$24*J33/Params!$D$26) | M33: =IF(AND(K33<0.0001,J33=0,I33>0),0,Phu_tai!$D$13+Phu_tai!$D$25*J33/Params!$D$26)
A34: Lht | B34: Chiều dài hành trình suy ra | C34: L_ht | D34: =Params!$D$12*(Phu_tai!$D$33+Phu_tai!$D$18) | E34: m | F34: Kiểm tra hợp lý với khẩu độ | I34: =32*Phu_tai!$D$39 | J34: =IF(I34<Phu_tai!$D$15,Params!$D$27*I34,IF(I34<Phu_tai!$D$15+Phu_tai!$D$17,Params!$D$26,IF(I34<Phu_tai!$D$18,Params!$D$26-Params!$D$27*(I34-Phu_tai!$D$15-Phu_tai!$D$17),0)))+IF(AND((I34-Phu_tai!$D$18-Phu_tai!$D$40)>=0,(I34-Phu_tai!$D$18-Phu_tai!$D$40)<Phu_tai!$D$18),-(IF((I34-Phu_tai!$D$18-Phu_tai!$D$40)<Phu_tai!$D$15,Params!$D$27*(I34-Phu_tai!$D$18-Phu_tai!$D$40),IF((I34-Phu_tai!$D$18-Phu_tai!$D$40)<Phu_tai!$D$15+Phu_tai!$D$17,Params!$D$26,Params!$D$26-Params!$D$27*((I34-Phu_tai!$D$18-Phu_tai!$D$40)-Phu_tai!$D$15-Phu_tai!$D$17)))),0) | K34: =MAX(0,K33+(J34+J33)/2*Phu_tai!$D$39) | L34: =IF(AND(K34<0.0001,J34=0,I34>0),0,Phu_tai!$D$12+Phu_tai!$D$24*J34/Params!$D$26) | M34: =IF(AND(K34<0.0001,J34=0,I34>0),0,Phu_tai!$D$13+Phu_tai!$D$25*J34/Params!$D$26)
A35: S1 | B35: Σ M²t hành trình đầy tải | C35: ΣM²t | D35: =Phu_tai!$D$12^2*Phu_tai!$D$32+2*Phu_tai!$D$18*Phu_tai!$D$24^2*Phu_tai!$D$20 | E35: N²m²s | F35: Số hạng chéo tăng/giảm tốc triệt tiêu | I35: =33*Phu_tai!$D$39 | J35: =IF(I35<Phu_tai!$D$15,Params!$D$27*I35,IF(I35<Phu_tai!$D$15+Phu_tai!$D$17,Params!$D$26,IF(I35<Phu_tai!$D$18,Params!$D$26-Params!$D$27*(I35-Phu_tai!$D$15-Phu_tai!$D$17),0)))+IF(AND((I35-Phu_tai!$D$18-Phu_tai!$D$40)>=0,(I35-Phu_tai!$D$18-Phu_tai!$D$40)<Phu_tai!$D$18),-(IF((I35-Phu_tai!$D$18-Phu_tai!$D$40)<Phu_tai!$D$15,Params!$D$27*(I35-Phu_tai!$D$18-Phu_tai!$D$40),IF((I35-Phu_tai!$D$18-Phu_tai!$D$40)<Phu_tai!$D$15+Phu_tai!$D$17,Params!$D$26,Params!$D$26-Params!$D$27*((I35-Phu_tai!$D$18-Phu_tai!$D$40)-Phu_tai!$D$15-Phu_tai!$D$17)))),0) | K35: =MAX(0,K34+(J35+J34)/2*Phu_tai!$D$39) | L35: =IF(AND(K35<0.0001,J35=0,I35>0),0,Phu_tai!$D$12+Phu_tai!$D$24*J35/Params!$D$26) | M35: =IF(AND(K35<0.0001,J35=0,I35>0),0,Phu_tai!$D$13+Phu_tai!$D$25*J35/Params!$D$26)
A36: S0 | B36: Σ M²t hành trình không tải | C36: ΣM²t,0 | D36: =Phu_tai!$D$13^2*Phu_tai!$D$32+2*Phu_tai!$D$18*Phu_tai!$D$25^2*Phu_tai!$D$20 | E36: N²m²s | I36: =34*Phu_tai!$D$39 | J36: =IF(I36<Phu_tai!$D$15,Params!$D$27*I36,IF(I36<Phu_tai!$D$15+Phu_tai!$D$17,Params!$D$26,IF(I36<Phu_tai!$D$18,Params!$D$26-Params!$D$27*(I36-Phu_tai!$D$15-Phu_tai!$D$17),0)))+IF(AND((I36-Phu_tai!$D$18-Phu_tai!$D$40)>=0,(I36-Phu_tai!$D$18-Phu_tai!$D$40)<Phu_tai!$D$18),-(IF((I36-Phu_tai!$D$18-Phu_tai!$D$40)<Phu_tai!$D$15,Params!$D$27*(I36-Phu_tai!$D$18-Phu_tai!$D$40),IF((I36-Phu_tai!$D$18-Phu_tai!$D$40)<Phu_tai!$D$15+Phu_tai!$D$17,Params!$D$26,Params!$D$26-Params!$D$27*((I36-Phu_tai!$D$18-Phu_tai!$D$40)-Phu_tai!$D$15-Phu_tai!$D$17)))),0) | K36: =MAX(0,K35+(J36+J35)/2*Phu_tai!$D$39) | L36: =IF(AND(K36<0.0001,J36=0,I36>0),0,Phu_tai!$D$12+Phu_tai!$D$24*J36/Params!$D$26) | M36: =IF(AND(K36<0.0001,J36=0,I36>0),0,Phu_tai!$D$13+Phu_tai!$D$25*J36/Params!$D$26)
A37: Mdt | B37: Mô-men đẳng trị nhiệt | C37: M_đt | D37: =SQRT((Phu_tai!$D$35+Phu_tai!$D$36)/Phu_tai!$D$31) | E37: N·m | F37: √(ΣM²t/Σt_lv) | I37: =35*Phu_tai!$D$39 | J37: =IF(I37<Phu_tai!$D$15,Params!$D$27*I37,IF(I37<Phu_tai!$D$15+Phu_tai!$D$17,Params!$D$26,IF(I37<Phu_tai!$D$18,Params!$D$26-Params!$D$27*(I37-Phu_tai!$D$15-Phu_tai!$D$17),0)))+IF(AND((I37-Phu_tai!$D$18-Phu_tai!$D$40)>=0,(I37-Phu_tai!$D$18-Phu_tai!$D$40)<Phu_tai!$D$18),-(IF((I37-Phu_tai!$D$18-Phu_tai!$D$40)<Phu_tai!$D$15,Params!$D$27*(I37-Phu_tai!$D$18-Phu_tai!$D$40),IF((I37-Phu_tai!$D$18-Phu_tai!$D$40)<Phu_tai!$D$15+Phu_tai!$D$17,Params!$D$26,Params!$D$26-Params!$D$27*((I37-Phu_tai!$D$18-Phu_tai!$D$40)-Phu_tai!$D$15-Phu_tai!$D$17)))),0) | K37: =MAX(0,K36+(J37+J36)/2*Phu_tai!$D$39) | L37: =IF(AND(K37<0.0001,J37=0,I37>0),0,Phu_tai!$D$12+Phu_tai!$D$24*J37/Params!$D$26) | M37: =IF(AND(K37<0.0001,J37=0,I37>0),0,Phu_tai!$D$13+Phu_tai!$D$25*J37/Params!$D$26)
A38: F. Đồ thị phụ tải một hành trình đầy tải (chạy đều rút gọn 1 s) — bảng bên phải, cột I..M | I38: =36*Phu_tai!$D$39 | J38: =IF(I38<Phu_tai!$D$15,Params!$D$27*I38,IF(I38<Phu_tai!$D$15+Phu_tai!$D$17,Params!$D$26,IF(I38<Phu_tai!$D$18,Params!$D$26-Params!$D$27*(I38-Phu_tai!$D$15-Phu_tai!$D$17),0)))+IF(AND((I38-Phu_tai!$D$18-Phu_tai!$D$40)>=0,(I38-Phu_tai!$D$18-Phu_tai!$D$40)<Phu_tai!$D$18),-(IF((I38-Phu_tai!$D$18-Phu_tai!$D$40)<Phu_tai!$D$15,Params!$D$27*(I38-Phu_tai!$D$18-Phu_tai!$D$40),IF((I38-Phu_tai!$D$18-Phu_tai!$D$40)<Phu_tai!$D$15+Phu_tai!$D$17,Params!$D$26,Params!$D$26-Params!$D$27*((I38-Phu_tai!$D$18-Phu_tai!$D$40)-Phu_tai!$D$15-Phu_tai!$D$17)))),0) | K38: =MAX(0,K37+(J38+J37)/2*Phu_tai!$D$39) | L38: =IF(AND(K38<0.0001,J38=0,I38>0),0,Phu_tai!$D$12+Phu_tai!$D$24*J38/Params!$D$26) | M38: =IF(AND(K38<0.0001,J38=0,I38>0),0,Phu_tai!$D$13+Phu_tai!$D$25*J38/Params!$D$26)
A39: dt | B39: Bước thời gian đồ thị | C39: Δt | D39: 0.02 | E39: s | I39: =37*Phu_tai!$D$39 | J39: =IF(I39<Phu_tai!$D$15,Params!$D$27*I39,IF(I39<Phu_tai!$D$15+Phu_tai!$D$17,Params!$D$26,IF(I39<Phu_tai!$D$18,Params!$D$26-Params!$D$27*(I39-Phu_tai!$D$15-Phu_tai!$D$17),0)))+IF(AND((I39-Phu_tai!$D$18-Phu_tai!$D$40)>=0,(I39-Phu_tai!$D$18-Phu_tai!$D$40)<Phu_tai!$D$18),-(IF((I39-Phu_tai!$D$18-Phu_tai!$D$40)<Phu_tai!$D$15,Params!$D$27*(I39-Phu_tai!$D$18-Phu_tai!$D$40),IF((I39-Phu_tai!$D$18-Phu_tai!$D$40)<Phu_tai!$D$15+Phu_tai!$D$17,Params!$D$26,Params!$D$26-Params!$D$27*((I39-Phu_tai!$D$18-Phu_tai!$D$40)-Phu_tai!$D$15-Phu_tai!$D$17)))),0) | K39: =MAX(0,K38+(J39+J38)/2*Phu_tai!$D$39) | L39: =IF(AND(K39<0.0001,J39=0,I39>0),0,Phu_tai!$D$12+Phu_tai!$D$24*J39/Params!$D$26) | M39: =IF(AND(K39<0.0001,J39=0,I39>0),0,Phu_tai!$D$13+Phu_tai!$D$25*J39/Params!$D$26)
A40: Tshow | B40: Thời gian chạy đều hiển thị | C40: T_hiển thị | D40: 1 | E40: s | F40: Thực tế ≈ t_đều | I40: =38*Phu_tai!$D$39 | J40: =IF(I40<Phu_tai!$D$15,Params!$D$27*I40,IF(I40<Phu_tai!$D$15+Phu_tai!$D$17,Params!$D$26,IF(I40<Phu_tai!$D$18,Params!$D$26-Params!$D$27*(I40-Phu_tai!$D$15-Phu_tai!$D$17),0)))+IF(AND((I40-Phu_tai!$D$18-Phu_tai!$D$40)>=0,(I40-Phu_tai!$D$18-Phu_tai!$D$40)<Phu_tai!$D$18),-(IF((I40-Phu_tai!$D$18-Phu_tai!$D$40)<Phu_tai!$D$15,Params!$D$27*(I40-Phu_tai!$D$18-Phu_tai!$D$40),IF((I40-Phu_tai!$D$18-Phu_tai!$D$40)<Phu_tai!$D$15+Phu_tai!$D$17,Params!$D$26,Params!$D$26-Params!$D$27*((I40-Phu_tai!$D$18-Phu_tai!$D$40)-Phu_tai!$D$15-Phu_tai!$D$17)))),0) | K40: =MAX(0,K39+(J40+J39)/2*Phu_tai!$D$39) | L40: =IF(AND(K40<0.0001,J40=0,I40>0),0,Phu_tai!$D$12+Phu_tai!$D$24*J40/Params!$D$26) | M40: =IF(AND(K40<0.0001,J40=0,I40>0),0,Phu_tai!$D$13+Phu_tai!$D$25*J40/Params!$D$26)
...

Sheet Chon_DC
A1: Mã | B1: Đại lượng | C1: Ký hiệu | D1: Ứng viên 1 | E1: Ứng viên 2 | F1: Ứng viên 3 | G1: Ứng viên 4 | H1: Đơn vị | I1: Ghi chú
A2: A. So sánh 4 động cơ ứng viên tại lượng đặt a*, ρ* (sheet Params)
A3: name | B3: Mã động cơ | D3: =Catalogue!$D$6 | E3: =Catalogue!$E$6 | F3: =Catalogue!$F$6 | G3: =Catalogue!$G$6
A4: PN | B4: Công suất định mức S1 | C4: P_N | D4: =Catalogue!$D$7 | E4: =Catalogue!$E$7 | F4: =Catalogue!$F$7 | G4: =Catalogue!$G$7 | H4: kW
A5: wN | B5: Tốc độ góc định mức | C5: ω_N | D5: =Catalogue!$D$9*2*PI()/60 | E5: =Catalogue!$E$9*2*PI()/60 | F5: =Catalogue!$F$9*2*PI()/60 | G5: =Catalogue!$G$9*2*PI()/60 | H5: rad/s
A6: iyc | B6: Tỷ số truyền yêu cầu | C6: i_yc | D6: =Chon_DC!$D$5/Phu_tai!$D$3 | E6: =Chon_DC!$E$5/Phu_tai!$D$3 | F6: =Chon_DC!$F$5/Phu_tai!$D$3 | G6: =Chon_DC!$G$5/Phu_tai!$D$3 | H6: - | I6: So với i_thực = 155.34
A7: Mc_MN | B7: Tải tĩnh đầy tải / M_N | C7: M_c/M_N | D7: =Phu_tai!$D$12/Catalogue!$D$8 | E7: =Phu_tai!$D$12/Catalogue!$E$8 | F7: =Phu_tai!$D$12/Catalogue!$F$8 | G7: =Phu_tai!$D$12/Catalogue!$G$8 | H7: - | I7: > 1: quá tải liên tục khi chạy đều 120 s
A8: Mmax | B8: Mô-men đỉnh khi tăng tốc đầy tải | C8: M_max | D8: =Phu_tai!$D$12+Params!$D$28*Params!$D$6*Params!$D$26*Phu_tai!$D$9/Params!$D$18+Catalogue!$D$15*Params!$D$26/Phu_tai!$D$9 | E8: =Phu_tai!$D$12+Params!$D$28*Params!$D$6*Params!$D$26*Phu_tai!$D$9/Params!$D$18+Catalogue!$E$15*Params!$D$26/Phu_tai!$D$9 | F8: =Phu_tai!$D$12+Params!$D$28*Params!$D$6*Params!$D$26*Phu_tai!$D$9/Params!$D$18+Catalogue!$F$15*Params!$D$26/Phu_tai!$D$9 | G8: =Phu_tai!$D$12+Params!$D$28*Params!$D$6*Params!$D$26*Phu_tai!$D$9/Params!$D$18+Catalogue!$G$15*Params!$D$26/Phu_tai!$D$9 | H8: N·m
A9: rM | B9: Bội số yêu cầu | C9: M_max/M_N | D9: =Chon_DC!$D$8/Catalogue!$D$8 | E9: =Chon_DC!$E$8/Catalogue!$E$8 | F9: =Chon_DC!$F$8/Catalogue!$F$8 | G9: =Chon_DC!$G$8/Catalogue!$G$8 | H9: -
A10: lav | B10: Bội số khả dụng ở lưới −10% | C10: λ_K(U_min/U_N)² | D10: =Catalogue!$D$14*(Params!$D$21*(1-Params!$D$22)/Params!$D$34)^2 | E10: =Catalogue!$E$14*(Params!$D$21*(1-Params!$D$22)/Params!$D$34)^2 | F10: =Catalogue!$F$14*(Params!$D$21*(1-Params!$D$22)/Params!$D$34)^2 | G10: =Catalogue!$G$14*(Params!$D$21*(1-Params!$D$22)/Params!$D$34)^2 | H10: - | I10: M_K ∝ U²
A11: klam | B11: Hệ số dự trữ quá tải | C11: k_λ | D11: =Chon_DC!$D$10/Chon_DC!$D$9 | E11: =Chon_DC!$E$10/Chon_DC!$E$9 | F11: =Chon_DC!$F$10/Chon_DC!$F$9 | G11: =Chon_DC!$G$10/Chon_DC!$G$9 | H11: - | I11: Yêu cầu ≥ k_λ,min
A12: Pdt | B12: Công suất đẳng trị S3-40% | C12: P_đt | D12: =Phu_tai!$D$37*Chon_DC!$D$5 | E12: =Phu_tai!$D$37*Chon_DC!$E$5 | F12: =Phu_tai!$D$37*Chon_DC!$F$5 | G12: =Phu_tai!$D$37*Chon_DC!$G$5 | H12: W | I12: M_đt·ω_N
A13: kdt | B13: Hệ số dự trữ nhiệt | C13: k_dt | D13: =Catalogue!$D$7*1000/Chon_DC!$D$12 | E13: =Catalogue!$E$7*1000/Chon_DC!$E$12 | F13: =Catalogue!$F$7*1000/Chon_DC!$F$12 | G13: =Catalogue!$G$7*1000/Chon_DC!$G$12 | H13: - | I13: P_N(S1)/P_đt — bảo thủ (chưa quy đổi S3)
A14: ok | B14: Kết luận | D14: =IF(AND(Chon_DC!$D$13>=Params!$D$32,Chon_DC!$D$11>=Params!$D$33,Chon_DC!$D$7<=1),"ĐẠT","KHÔNG ĐẠT") | E14: =IF(AND(Chon_DC!$E$13>=Params!$D$32,Chon_DC!$E$11>=Params!$D$33,Chon_DC!$E$7<=1),"ĐẠT","KHÔNG ĐẠT") | F14: =IF(AND(Chon_DC!$F$13>=Params!$D$32,Chon_DC!$F$11>=Params!$D$33,Chon_DC!$F$7<=1),"ĐẠT","KHÔNG ĐẠT") | G14: =IF(AND(Chon_DC!$G$13>=Params!$D$32,Chon_DC!$G$11>=Params!$D$33,Chon_DC!$G$7<=1),"ĐẠT","KHÔNG ĐẠT")
B15: Động cơ chọn: ứng viên ĐẠT có công suất nhỏ nhất → nhập số cột vào Catalogue!sel_mot | D15: =IF(Chon_DC!$D$14="ĐẠT",1,IF(Chon_DC!$E$14="ĐẠT",2,IF(Chon_DC!$F$14="ĐẠT",3,IF(Chon_DC!$G$14="ĐẠT",4,0))))
A17: B. Ảnh hưởng của gia tốc đặt a* tới mô-men đỉnh (đầy tải, J_B = 26.2×10⁻⁴ kg·m²) — căn cứ CR-19
B18: a* (m/s²) | C18: ρ* = 4·a* | D18: t_acc (s) | E18: M_max (N·m) | F18: Động cơ nhỏ nhất đạt k_λ ≥ 1.2
B19: 0.45 | C19: =4*B19 | D19: =IF(B19^2/C19<Params!$D$12,Params!$D$12/B19+B19/C19,2*SQRT(Params!$D$12/C19)) | E19: =Phu_tai!$D$12+(Params!$D$28*Params!$D$6*Phu_tai!$D$9/Params!$D$18+0.00262/Phu_tai!$D$9)*MIN(B19,SQRT(Params!$D$12*C19)) | F19: =IF(AND(Chon_DC!$D$10/(E19/Catalogue!$D$8)>=Params!$D$33,Phu_tai!$D$12/Catalogue!$D$8<=1,Catalogue!$D$7*1000/(Phu_tai!$D$37*Chon_DC!$D$5)>=Params!$D$32),Catalogue!$D$6,IF(AND(Chon_DC!$E$10/(E19/Catalogue!$E$8)>=Params!$D$33,Phu_tai!$D$12/Catalogue!$E$8<=1,Catalogue!$E$7*1000/(Phu_tai!$D$37*Chon_DC!$E$5)>=Params!$D$32),Catalogue!$E$6,IF(AND(Chon_DC!$F$10/(E19/Catalogue!$F$8)>=Params!$D$33,Phu_tai!$D$12/Catalogue!$F$8<=1,Catalogue!$F$7*1000/(Phu_tai!$D$37*Chon_DC!$F$5)>=Params!$D$32),Catalogue!$F$6,IF(AND(Chon_DC!$G$10/(E19/Catalogue!$G$8)>=Params!$D$33,Phu_tai!$D$12/Catalogue!$G$8<=1,Catalogue!$G$7*1000/(Phu_tai!$D$37*Chon_DC!$G$5)>=Params!$D$32),Catalogue!$G$6,"> 0.75 kW"))))
B20: 0.3 | C20: =4*B20 | D20: =IF(B20^2/C20<Params!$D$12,Params!$D$12/B20+B20/C20,2*SQRT(Params!$D$12/C20)) | E20: =Phu_tai!$D$12+(Params!$D$28*Params!$D$6*Phu_tai!$D$9/Params!$D$18+0.00262/Phu_tai!$D$9)*MIN(B20,SQRT(Params!$D$12*C20)) | F20: =IF(AND(Chon_DC!$D$10/(E20/Catalogue!$D$8)>=Params!$D$33,Phu_tai!$D$12/Catalogue!$D$8<=1,Catalogue!$D$7*1000/(Phu_tai!$D$37*Chon_DC!$D$5)>=Params!$D$32),Catalogue!$D$6,IF(AND(Chon_DC!$E$10/(E20/Catalogue!$E$8)>=Params!$D$33,Phu_tai!$D$12/Catalogue!$E$8<=1,Catalogue!$E$7*1000/(Phu_tai!$D$37*Chon_DC!$E$5)>=Params!$D$32),Catalogue!$E$6,IF(AND(Chon_DC!$F$10/(E20/Catalogue!$F$8)>=Params!$D$33,Phu_tai!$D$12/Catalogue!$F$8<=1,Catalogue!$F$7*1000/(Phu_tai!$D$37*Chon_DC!$F$5)>=Params!$D$32),Catalogue!$F$6,IF(AND(Chon_DC!$G$10/(E20/Catalogue!$G$8)>=Params!$D$33,Phu_tai!$D$12/Catalogue!$G$8<=1,Catalogue!$G$7*1000/(Phu_tai!$D$37*Chon_DC!$G$5)>=Params!$D$32),Catalogue!$G$6,"> 0.75 kW"))))
B21: 0.2 | C21: =4*B21 | D21: =IF(B21^2/C21<Params!$D$12,Params!$D$12/B21+B21/C21,2*SQRT(Params!$D$12/C21)) | E21: =Phu_tai!$D$12+(Params!$D$28*Params!$D$6*Phu_tai!$D$9/Params!$D$18+0.00262/Phu_tai!$D$9)*MIN(B21,SQRT(Params!$D$12*C21)) | F21: =IF(AND(Chon_DC!$D$10/(E21/Catalogue!$D$8)>=Params!$D$33,Phu_tai!$D$12/Catalogue!$D$8<=1,Catalogue!$D$7*1000/(Phu_tai!$D$37*Chon_DC!$D$5)>=Params!$D$32),Catalogue!$D$6,IF(AND(Chon_DC!$E$10/(E21/Catalogue!$E$8)>=Params!$D$33,Phu_tai!$D$12/Catalogue!$E$8<=1,Catalogue!$E$7*1000/(Phu_tai!$D$37*Chon_DC!$E$5)>=Params!$D$32),Catalogue!$E$6,IF(AND(Chon_DC!$F$10/(E21/Catalogue!$F$8)>=Params!$D$33,Phu_tai!$D$12/Catalogue!$F$8<=1,Catalogue!$F$7*1000/(Phu_tai!$D$37*Chon_DC!$F$5)>=Params!$D$32),Catalogue!$F$6,IF(AND(Chon_DC!$G$10/(E21/Catalogue!$G$8)>=Params!$D$33,Phu_tai!$D$12/Catalogue!$G$8<=1,Catalogue!$G$7*1000/(Phu_tai!$D$37*Chon_DC!$G$5)>=Params!$D$32),Catalogue!$G$6,"> 0.75 kW"))))
B22: 0.1 | C22: =4*B22 | D22: =IF(B22^2/C22<Params!$D$12,Params!$D$12/B22+B22/C22,2*SQRT(Params!$D$12/C22)) | E22: =Phu_tai!$D$12+(Params!$D$28*Params!$D$6*Phu_tai!$D$9/Params!$D$18+0.00262/Phu_tai!$D$9)*MIN(B22,SQRT(Params!$D$12*C22)) | F22: =IF(AND(Chon_DC!$D$10/(E22/Catalogue!$D$8)>=Params!$D$33,Phu_tai!$D$12/Catalogue!$D$8<=1,Catalogue!$D$7*1000/(Phu_tai!$D$37*Chon_DC!$D$5)>=Params!$D$32),Catalogue!$D$6,IF(AND(Chon_DC!$E$10/(E22/Catalogue!$E$8)>=Params!$D$33,Phu_tai!$D$12/Catalogue!$E$8<=1,Catalogue!$E$7*1000/(Phu_tai!$D$37*Chon_DC!$E$5)>=Params!$D$32),Catalogue!$E$6,IF(AND(Chon_DC!$F$10/(E22/Catalogue!$F$8)>=Params!$D$33,Phu_tai!$D$12/Catalogue!$F$8<=1,Catalogue!$F$7*1000/(Phu_tai!$D$37*Chon_DC!$F$5)>=Params!$D$32),Catalogue!$F$6,IF(AND(Chon_DC!$G$10/(E22/Catalogue!$G$8)>=Params!$D$33,Phu_tai!$D$12/Catalogue!$G$8<=1,Catalogue!$G$7*1000/(Phu_tai!$D$37*Chon_DC!$G$5)>=Params!$D$32),Catalogue!$G$6,"> 0.75 kW"))))
B23: 0.06 | C23: =4*B23 | D23: =IF(B23^2/C23<Params!$D$12,Params!$D$12/B23+B23/C23,2*SQRT(Params!$D$12/C23)) | E23: =Phu_tai!$D$12+(Params!$D$28*Params!$D$6*Phu_tai!$D$9/Params!$D$18+0.00262/Phu_tai!$D$9)*MIN(B23,SQRT(Params!$D$12*C23)) | F23: =IF(AND(Chon_DC!$D$10/(E23/Catalogue!$D$8)>=Params!$D$33,Phu_tai!$D$12/Catalogue!$D$8<=1,Catalogue!$D$7*1000/(Phu_tai!$D$37*Chon_DC!$D$5)>=Params!$D$32),Catalogue!$D$6,IF(AND(Chon_DC!$E$10/(E23/Catalogue!$E$8)>=Params!$D$33,Phu_tai!$D$12/Catalogue!$E$8<=1,Catalogue!$E$7*1000/(Phu_tai!$D$37*Chon_DC!$E$5)>=Params!$D$32),Catalogue!$E$6,IF(AND(Chon_DC!$F$10/(E23/Catalogue!$F$8)>=Params!$D$33,Phu_tai!$D$12/Catalogue!$F$8<=1,Catalogue!$F$7*1000/(Phu_tai!$D$37*Chon_DC!$F$5)>=Params!$D$32),Catalogue!$F$6,IF(AND(Chon_DC!$G$10/(E23/Catalogue!$G$8)>=Params!$D$33,Phu_tai!$D$12/Catalogue!$G$8<=1,Catalogue!$G$7*1000/(Phu_tai!$D$37*Chon_DC!$G$5)>=Params!$D$32),Catalogue!$G$6,"> 0.75 kW"))))
B24: Ghi chú: cột F kiểm điều kiện nhiệt bằng M_đt của a* đang chọn (ảnh hưởng của a* tới M_đt rất nhỏ vì pha tăng tốc chỉ ≈ 1% thời gian đóng điện).

Sheet Tham_so_DC
A1: Mã | B1: Đại lượng | C1: Ký hiệu | D1: Giá trị | E1: Đơn vị | F1: Công thức (Class_3 slide 9–11) | G1: Ghi chú
A2: A. Thông số nhãn máy động cơ đang chọn — [W-01]
A3: name | B3: Mã động cơ | D3: =Catalogue!$H$6
A4: Uph | B4: Điện áp pha (đấu Y) | C4: U_ph | D4: =Params!$D$34/SQRT(3) | E4: V | F4: U_N/√3
A5: Iph | B5: Dòng pha định mức | C5: I_ph | D5: =Catalogue!$H$10 | E5: A
A6: nN | B6: Tốc độ định mức | C6: N_n | D6: =Catalogue!$H$9 | E6: vg/ph
A7: cos | B7: Hệ số công suất | C7: cosφ | D7: =Catalogue!$H$11 | E7: -
A8: MN | B8: Mô-men định mức | C8: M_N | D8: =Catalogue!$H$8 | E8: N·m
A9: lamK | B9: Bội số mô-men tới hạn | C9: λ_K | D9: =Catalogue!$H$14 | E9: -
A10: ws | B10: Tần số góc nguồn | C10: ω_s | D10: =2*PI()*Params!$D$23 | E10: rad/s | F10: 2πf
A11: Ns | B11: Tốc độ đồng bộ | C11: N_s | D11: =60*Params!$D$23/Params!$D$35 | E11: vg/ph | F11: 60f/p
A12: B. 14 công thức ước lượng tham số động cơ
A13: CT1 | B13: 1. Công suất điện đầu vào | C13: P_e,n | D13: =3*Tham_so_DC!$D$4*Tham_so_DC!$D$5*Tham_so_DC!$D$7 | E13: W | F13: 3·U_ph·I_ph·cosφ | G13: Công suất điện, không phải P_N cơ
A14: CT2 | B14: 2. Tổng trở pha | C14: Z_ph | D14: =Tham_so_DC!$D$4/Tham_so_DC!$D$5 | E14: Ω | F14: U_ph/I_ph
A15: CT3 | B15: 3. Hệ số trượt định mức | C15: s_n | D15: =(Tham_so_DC!$D$11-Tham_so_DC!$D$6)/Tham_so_DC!$D$11 | E15: - | F15: (N_s − N_n)/N_s
A16: CT4 | B16: 4. Điện trở rotor | C16: R_r | D16: =Tham_so_DC!$D$15*Tham_so_DC!$D$14 | E16: Ω | F16: s_n·Z_ph
A17: CT5a | B17: 5a. Dòng trục d định mức | C17: I_sd,n | D17: =SQRT(2)*Tham_so_DC!$D$5*SQRT(1-Tham_so_DC!$D$7) | E17: A | F17: √2·I_ph·√(1 − cosφ)
A18: CT5b | B18: 5b. Dòng trục q định mức | C18: I_sq,n | D18: =SQRT(2*Tham_so_DC!$D$5^2-Tham_so_DC!$D$17^2) | E18: A | F18: √(2I_ph² − I_sd²)
A19: CT6 | B19: 6. Tốc độ trượt | C19: ω_sl,n | D19: =Tham_so_DC!$D$10-Params!$D$35*2*PI()*Tham_so_DC!$D$6/60 | E19: rad/s | F19: 2πf − p·2πN_n/60
A20: CT7 | B20: 7. Hằng số thời gian rotor | C20: T_r | D20: =Tham_so_DC!$D$18/(Tham_so_DC!$D$19*Tham_so_DC!$D$17) | E20: s | F20: I_sq/(ω_sl·I_sd)
A21: CT8 | B21: 8. Điện kháng tản tổng | C21: X_σ | D21: =(SQRT(1-Tham_so_DC!$D$7^2)-Tham_so_DC!$D$7*Tham_so_DC!$D$17/Tham_so_DC!$D$18)*Tham_so_DC!$D$14 | E21: Ω | F21: (sinφ − cosφ·I_sd/I_sq)·U_ph/I_ph
A22: CT9 | B22: 9. Điện kháng chính stator | C22: X_s | D22: =SQRT(2)*Tham_so_DC!$D$4/Tham_so_DC!$D$17-Tham_so_DC!$D$21 | E22: Ω | F22: √2·U_ph/I_sd − X_σ
A23: CT10 | B23: 10. Điện trở stator | C23: R_s | D23: =Tham_so_DC!$D$19/Tham_so_DC!$D$10*Tham_so_DC!$D$17/Tham_so_DC!$D$18*Tham_so_DC!$D$22 | E23: Ω | F23: (ω_sl/ω_s)·(I_sd/I_sq)·X_s | G23: Giả thiết R_s ≈ R_r
A24: CT11 | B24: 11. Hệ số tản | C24: σ | D24: =Tham_so_DC!$D$21/Tham_so_DC!$D$22 | E24: - | F24: X_σ/X_s
A25: CT12 | B25: 12. Hằng số thời gian stator | C25: T_s | D25: =Tham_so_DC!$D$22/(Tham_so_DC!$D$10*Tham_so_DC!$D$23) | E25: s | F25: X_s/(ω_s·R_s) | G25: Thay CT10 vào ⇒ T_s ≡ T_r (trùng nhau do cách lập công thức, không phải lỗi tính)
A26: CT13 | B26: 13. Điện cảm rotor | C26: L_r | D26: =Tham_so_DC!$D$20*Tham_so_DC!$D$16 | E26: H | F26: T_r·R_r
A27: Ls | B27: (phụ) Điện cảm stator | C27: L_s | D27: =Tham_so_DC!$D$22/Tham_so_DC!$D$10 | E27: H | F27: X_s/ω_s
A28: CT14 | B28: 14. Hỗ cảm | C28: L_m | D28: =SQRT(Tham_so_DC!$D$27*Tham_so_DC!$D$26*(1-Tham_so_DC!$D$24)) | E28: H | F28: √(L_s·L_r·(1 − σ))
A29: C. Bộ hiệu chỉnh: R_s từ cân bằng công suất; R_r', L_σ, L_m khớp catalogue (I_N, cosφ_N, M_N, λ_K)
A30: Ploss | B30: Tổng tổn hao định mức | C30: ΣΔP | D30: =Catalogue!$H$7*1000/Catalogue!$H$12-Catalogue!$H$7*1000 | E30: W | F30: P_N/η − P_N
A31: Pcu2 | B31: Tổn hao đồng rotor | C31: ΔP_Cu2 | D31: =Tham_so_DC!$D$15/(1-Tham_so_DC!$D$15)*Catalogue!$H$7*1000 | E31: W | F31: s/(1 − s)·P_N
A32: Pcu1 | B32: Tổn hao đồng stator | C32: ΔP_Cu1 | D32: =Tham_so_DC!$D$30*(1-Params!$D$40)-Tham_so_DC!$D$31 | E32: W | F32: ΣΔP(1 − k_Fe) − ΔP_Cu2
A33: Rs_c | B33: Điện trở stator hiệu chỉnh | C33: R_s | D33: =Tham_so_DC!$D$32/(3*Tham_so_DC!$D$5^2) | E33: Ω | F33: ΔP_Cu1/(3I²) | G33: [B]
A34: Rr_c | B34: Điện trở rotor quy đổi hiệu chỉnh | C34: R_r' | D34: 17.312 | E34: Ω | F34: Giải tối thiểu tổng bình phương 4 sai số (Excel Solver) | G34: Giá trị cho DRN71M4; đổi động cơ phải giải lại
A35: Ll_c | B35: Điện cảm tản stator = rotor hiệu chỉnh | C35: L_σs = L_σr | D35: 0.0731 | E35: H | F35: Như trên; chia đều L_σ cho stator và rotor
A36: Lm_c | B36: Hỗ cảm hiệu chỉnh | C36: L_m | D36: 0.9049 | E36: H | F36: Như trên
A37: D. Kiểm chứng: mạch thay thế hình T tại U_N, f_N, s_n — cột D: 14 công thức; cột G: bộ hiệu chỉnh
A38: Rs | B38: R_s | C38: R_s | D38: =Tham_so_DC!$D$23 | E38: Ω | G38: =Tham_so_DC!$D$33
A39: Rr | B39: R_r' | C39: R_r' | D39: =Tham_so_DC!$D$16 | E39: Ω | G39: =Tham_so_DC!$D$34
A40: Lls | B40: L_σs | C40: L_σs | D40: =Tham_so_DC!$D$27-Tham_so_DC!$D$28 | E40: H | G40: =Tham_so_DC!$D$35
...

Sheet Thiet_bi
